Workbook

Sheet 표지
B2: 도담소프트(가상) 전기조서 · 정산표(WTB)
B3: 제7기 2024년 1월 1일 ~ 2024년 12월 31일 · 단위: 원 · 가상 자료(감사 실습용)
B4: 회사 | C4: 도담소프트(가상)
B5: 회계기간 | C5: 2024-01-01 ~ 2024-12-31 (제7기)
B6: 결산일 | C6: 2024-12-31
B7: 감사인 | C7: 한울감사반(가상)
B8: 적용 회계기준 | C8: 일반기업회계기준
B9: 조서번호 | C9: 8100B 정산표 · 8100A 수정사항
B10: 파일 판 | C10: v3.1 (감사보고서일 2025-03-12 최종)
B11: 작성 | C11: 서나래(가상) · 2025-02-20
B12: 검토 | C12: 정가상(가상) · 2025-03-05
B14: 중요성
B15: 구분 | C15: 금액 | D15: 기준
B16: 재무제표 전체 중요성 | C16: =ROUNDDOWN('공시용PL'!E5*1%,-5) -> 99900000 | D16: 매출액 9,990,547,268원의 1%(10만 원 미만 버림)
B17: 수행중요성 | C17: =ROUNDDOWN(C16*75%,0) -> 74925000 | D17: 전체 중요성의 75%
B18: 명백히 사소한 금액 | C18: =ROUNDDOWN(C16*5%,0) -> 4995000 | D18: 전체 중요성의 5%
B20: 검산(수식)
B21: 항목 | C21: 결과 | D21: 확인한 곳
B22: TB 차대(회사제시 · 수정 · 최종 · 전기) | C22: =IF(AND('TB'!E63="OK",'TB'!F63="OK",'TB'!H63="OK",'TB'!I63="OK"),"OK","확인") -> OK | D22: TB 차대 검산 줄
B23: 정산표 재무상태표 대차(회사 제시 · Final · 전기) | C23: =IF(AND('재무상태표'!D59="OK",'재무상태표'!G59="OK",'재무상태표'!H59="OK"),"OK","확인") -> OK | D23: 재무상태표 Check 줄
B24: 수정분개 차변 합계 = 대변 합계 | C24: ='AJE'!N14 -> OK | D24: AJE 합계 줄
B25: 당기순손익 대사(회사 제시 + 수정 = Final) | C25: ='AJE'!F22 -> OK | D25: AJE 당기순손익 대사
B26: 공시용BS = 정산표, 자산 = 부채와자본 | C26: =IF(AND('공시용BS'!D56="OK",'공시용BS'!E56="OK",'공시용BS'!F56="OK",'공시용BS'!D55="OK",'공시용BS'!E55="OK",'공시용BS'!F55="OK"),"OK","확인") -> OK | D26: 공시용BS 대사 두 줄
B27: 공시용PL 당기순이익 = 정산표 | C27: =IF(AND('공시용PL'!D43="OK",'공시용PL'!E43="OK",'공시용PL'!F43="OK"),"OK","확인") -> OK | D27: 공시용PL 대사 줄
B28: 자본변동표 당기말 · 전기말 = 공시용BS | C28: =IF(AND('공시용자본변동표'!H17="OK",'공시용자본변동표'!H19="OK"),"OK","확인") -> OK | D28: 공시용자본변동표 대사 두 줄
B29: CF정산표 배분 합계 = 계정 증감, 효과 합계 = 현금 증감 | C29: =IF(AND('CF정산표'!F38="OK",'CF정산표'!I36="OK"),"OK","확인") -> OK | D29: CF정산표 판정
B30: 현금흐름표 기말의 현금 = 재무상태표 현금및현금성자산 | C30: =IF(AND('공시용CF'!C43="OK",'공시용CF'!D43="OK"),"OK","확인") -> OK | D30: 공시용CF 대사 줄
B32: 시트
B33: 시트 | C33: 무엇을 담았나
B34: TB | C34: 회사제시 시산표(마감 전, 차변 +, 대변 −). 수정 열은 AJE 시트에서 계정코드로 SUMIFS. 전기 최종은 제6기 감사받은 시산표
B35: 재무상태표 · 손익계산서 | C35: 정산표. 계정마다 회사 제시 → 수정 → Final, 전기 Final, 증감과 판정(수행중요성 이상이고 10% 이상이면 「설명 필요」)
B36: AJE | C36: 감사 수정분개 3건(AJE)과 표시 재분류 1건(RJE). 회사 반영 여부, 손익 영향, 당기순손익 대사
B37: 공시용BS · 공시용PL | C37: 정산표 Final 을 공시용 계정과목으로 SUMIF 한 재무제표. 감사보고서 재무상태표 · 손익계산서와 같은 숫자
B38: 공시용자본변동표 | C38: 전기초부터 당기말까지 자본 변동. 기말은 공시용BS 와 대사
B39: CF정산표 · 공시용CF | C39: 계정별 증감을 현금흐름표 과목으로 배분(배분 합계 = 증감)하고 간접법 현금흐름표로 모음
B41: 범례
B42: 노란 칸 | C42: 회사 제시 금액과 감사인이 입력한 값
B43: 회색 칸 | C43: 전기 감사보고서 · 전기조서에서 옮긴 값
B44: 파란 글자 | C44: 다른 시트를 연결한 값
B45: t/m ✓ | C45: 회사 합계잔액시산표와 일치 확인
...

Sheet TB
A1: 수정후 시산표(TB) · 제7기 2024-12-31
A2: 회사제시는 회사가 낸 2024 합계잔액시산표(마감 전)다. 차변 +, 대변 −. 수정 열은 AJE 시트에서 계정코드로 SUMIFS 한다. 전기 최종은 제6기 감사받은 시산표(마감 전, 결손금은 2022 기말)다.
A4: 계정코드 | B4: 계정과목 | C4: 표시과목 | D4: 구분 | E4: 회사제시 | F4: 수정 차변 | G4: 수정 대변 | H4: 최종 | I4: 전기 최종 | J4: t/m | K4: 관련 조서
A5: 10300 | B5: 제예금 | C5: 현금및현금성자산 | D5: 자산 | E5: 2769582606 | F5: =SUMIFS('AJE'!$F$6:$F$13,'AJE'!$I$6:$I$13,$A5) -> 0 | G5: =SUMIFS('AJE'!$H$6:$H$13,'AJE'!$J$6:$J$13,$A5) -> 0 | H5: =E5+F5-G5 -> 2769582606 | I5: 3645038600 | J5: ✓ PY | K5: 4000A
A6: 10500 | B6: 정기예적금 | C6: 단기금융상품 | D6: 자산 | E6: 3000000000 | F6: =SUMIFS('AJE'!$F$6:$F$13,'AJE'!$I$6:$I$13,$A6) -> 0 | G6: =SUMIFS('AJE'!$H$6:$H$13,'AJE'!$J$6:$J$13,$A6) -> 0 | H6: =E6+F6-G6 -> 3000000000 | I6: 3000000000 | J6: ✓ PY | K6: 4000A
A7: 10800 | B7: 외상매출금 | C7: 매출채권 | D7: 자산 | E7: 681160188 | F7: =SUMIFS('AJE'!$F$6:$F$13,'AJE'!$I$6:$I$13,$A7) -> 0 | G7: =SUMIFS('AJE'!$H$6:$H$13,'AJE'!$J$6:$J$13,$A7) -> 0 | H7: =E7+F7-G7 -> 681160188 | I7: 540152971 | J7: ✓ PY | K7: 4000C
A8: 11600 | B8: 미수수익 | C8: 미수수익 | D8: 자산 | E8: 100032877 | F8: =SUMIFS('AJE'!$F$6:$F$13,'AJE'!$I$6:$I$13,$A8) -> 3528767 | G8: =SUMIFS('AJE'!$H$6:$H$13,'AJE'!$J$6:$J$13,$A8) -> 0 | H8: =E8+F8-G8 -> 103561644 | I8: 109002740 | J8: ✓ PY | K8: 4000A
A9: 13300 | B9: 선급비용 | C9: 선급비용 | D9: 자산 | E9: 0 | F9: =SUMIFS('AJE'!$F$6:$F$13,'AJE'!$I$6:$I$13,$A9) -> 45000000 | G9: =SUMIFS('AJE'!$H$6:$H$13,'AJE'!$J$6:$J$13,$A9) -> 0 | H9: =E9+F9-G9 -> 45000000 | I9: 0 | J9: ✓ PY | K9: 4000D
A10: 13500 | B10: 부가세대급금 | C10: 부가세대급금 | D10: 자산 | E10: 111738000 | F10: =SUMIFS('AJE'!$F$6:$F$13,'AJE'!$I$6:$I$13,$A10) -> 0 | G10: =SUMIFS('AJE'!$H$6:$H$13,'AJE'!$J$6:$J$13,$A10) -> 0 | H10: =E10+F10-G10 -> 111738000 | I10: 151000000 | J10: ✓ PY | K10: 4000D
A11: 13600 | B11: 선납세금 | C11: 당기법인세자산 | D11: 자산 | E11: 18609360 | F11: =SUMIFS('AJE'!$F$6:$F$13,'AJE'!$I$6:$I$13,$A11) -> 0 | G11: =SUMIFS('AJE'!$H$6:$H$13,'AJE'!$J$6:$J$13,$A11) -> 0 | H11: =E11+F11-G11 -> 18609360 | I11: 0 | J11: ✓ PY | K11: 4000T
A12: 17800 | B12: 투자유가증권 | C12: 지분법적용투자주식 | D12: 자산 | E12: 1180000000 | F12: =SUMIFS('AJE'!$F$6:$F$13,'AJE'!$I$6:$I$13,$A12) -> 0 | G12: =SUMIFS('AJE'!$H$6:$H$13,'AJE'!$J$6:$J$13,$A12) -> 1180000000 | H12: =E12+F12-G12 -> 0 | I12: 0 | J12: ✓ PY | K12: 4000F
A13: 18000 | B13: 지분법적용투자주식 | C13: 지분법적용투자주식 | D13: 자산 | E13: 0 | F13: =SUMIFS('AJE'!$F$6:$F$13,'AJE'!$I$6:$I$13,$A13) -> 1180000000 | G13: =SUMIFS('AJE'!$H$6:$H$13,'AJE'!$J$6:$J$13,$A13) -> 0 | H13: =E13+F13-G13 -> 1180000000 | I13: 1180000000 | J13: ✓ PY | K13: 4000F
A14: 17900 | B14: 장기대여금 | C14: 장기대여금 | D14: 자산 | E14: 60000000 | F14: =SUMIFS('AJE'!$F$6:$F$13,'AJE'!$I$6:$I$13,$A14) -> 0 | G14: =SUMIFS('AJE'!$H$6:$H$13,'AJE'!$J$6:$J$13,$A14) -> 0 | H14: =E14+F14-G14 -> 60000000 | I14: 60000000 | J14: ✓ PY | K14: 4000F
A15: 21200 | B15: 비품 | C15: 비품 | D15: 자산 | E15: 1245000000 | F15: =SUMIFS('AJE'!$F$6:$F$13,'AJE'!$I$6:$I$13,$A15) -> 0 | G15: =SUMIFS('AJE'!$H$6:$H$13,'AJE'!$J$6:$J$13,$A15) -> 0 | H15: =E15+F15-G15 -> 1245000000 | I15: 1130900000 | J15: ✓ PY | K15: 4000G
A16: 21300 | B16: 감가상각누계액 | C16: 감가상각누계액(비품) | D16: 자산 | E16: -771043482 | F16: =SUMIFS('AJE'!$F$6:$F$13,'AJE'!$I$6:$I$13,$A16) -> 0 | G16: =SUMIFS('AJE'!$H$6:$H$13,'AJE'!$J$6:$J$13,$A16) -> 0 | H16: =E16+F16-G16 -> -771043482 | I16: -493333152 | J16: ✓ PY | K16: 4000G
... A61: 93200 | B61: 외환차손 | C61: 외환차손 | D61: 비용 | E61: 1974589 | F61: =SUMIFS('AJE'!$F$6:$F$13,'AJE'!$I$6:$I$13,$A61) -> 0 | G61: =SUMIFS('AJE'!$H$6:$H$13,'AJE'!$J$6:$J$13,$A61) -> 0 | H61: =E61+F61-G61 -> 1974589 | I61: 2861370 | J61: ✓ PY | K61: 4000A
B62: 합계 | E62: =SUM(E5:E61) -> 0 | F62: =SUM(F5:F61) -> 1266928767 | G62: =SUM(G5:G61) -> 1266928767 | H62: =SUM(H5:H61) -> 0 | I62: =SUM(I5:I61) -> 0
B63: 차대 검산 | E63: =IF(ROUND(E62,0)=0,"OK","차대 불일치") -> OK | F63: =IF(ROUND(F62-G62,0)=0,"OK","차대 불일치") -> OK | H63: =IF(ROUND(H62,0)=0,"OK","차대 불일치") -> OK | I63: =IF(ROUND(I62,0)=0,"OK","차대 불일치") -> OK

Sheet 재무상태표
A1: 정산표(재무상태표)
A2: 제7기 2024-12-31 · 단위: 원 · 계정 줄은 TB 시트를 연결했다(자산 · 비용은 차변, 부채 · 자본 · 수익은 대변을 +로 보인다). 판정: |증감| 이 수행중요성 이상이고 증감률이 10% 이상이면 「설명 필요」
J3: 판정 기준 금액 | K3: ='표지'!$C$17 -> 74925000
J4: 판정 기준 비율 | K4: 0.1
A6: 코드 | B6: 회사 계정과목 | C6: 공시용 계정과목 | D6: 회사 제시 | E6: 수정 차변 | F6: 수정 대변 | G6: Final | H6: 전기 Final | I6: 증감 | J6: 증감률 | K6: 판정 | L6: 수정분개 | M6: 관련 조서
A7: 자산
B8: Ⅰ. 유동자산 | C8: 유동자산 | D8: =SUM(D9) -> 6681123031 | E8: =SUM(E9) -> 48528767 | F8: =SUM(F9) -> 0 | G8: =SUM(G9) -> 6729651798 | H8: =SUM(H9) -> 7445194311 | I8: =G8-H8 -> -715542513 | J8: =IF(H8=0,0,I8/ABS(H8)) -> -0.09610797
B9: (1) 당좌자산 | C9: 당좌자산 | D9: =SUM(D10,D11,D12,D13,D14,D15,D16) -> 6681123031 | E9: =SUM(E10,E11,E12,E13,E14,E15,E16) -> 48528767 | F9: =SUM(F10,F11,F12,F13,F14,F15,F16) -> 0 | G9: =SUM(G10,G11,G12,G13,G14,G15,G16) -> 6729651798 | H9: =SUM(H10,H11,H12,H13,H14,H15,H16) -> 7445194311 | I9: =G9-H9 -> -715542513 | J9: =IF(H9=0,0,I9/ABS(H9)) -> -0.09610797
A10: 10300 | B10: 제예금 | C10: 현금및현금성자산 | D10: ='TB'!E5 -> 2769582606 | E10: ='TB'!F5 -> 0 | F10: ='TB'!G5 -> 0 | G10: =D10+E10-F10 -> 2769582606 | H10: ='TB'!I5 -> 3645038600 | I10: =G10-H10 -> -875455994 | J10: =IF(H10=0,0,I10/ABS(H10)) -> -0.24017743 | K10: =IF(AND(ABS(I10)>=$K$3,OR(H10=0,ABS(J10)>=$K$4)),"설명 필요","") -> 설명 필요 | M10: 4000A
A11: 10500 | B11: 정기예적금 | C11: 단기금융상품 | D11: ='TB'!E6 -> 3000000000 | E11: ='TB'!F6 -> 0 | F11: ='TB'!G6 -> 0 | G11: =D11+E11-F11 -> 3000000000 | H11: ='TB'!I6 -> 3000000000 | I11: =G11-H11 -> 0 | J11: =IF(H11=0,0,I11/ABS(H11)) -> 0 | K11: =IF(AND(ABS(I11)>=$K$3,OR(H11=0,ABS(J11)>=$K$4)),"설명 필요","") | M11: 4000A
A12: 10800 | B12: 외상매출금 | C12: 매출채권 | D12: ='TB'!E7 -> 681160188 | E12: ='TB'!F7 -> 0 | F12: ='TB'!G7 -> 0 | G12: =D12+E12-F12 -> 681160188 | H12: ='TB'!I7 -> 540152971 | I12: =G12-H12 -> 141007217 | J12: =IF(H12=0,0,I12/ABS(H12)) -> 0.26105053 | K12: =IF(AND(ABS(I12)>=$K$3,OR(H12=0,ABS(J12)>=$K$4)),"설명 필요","") -> 설명 필요 | M12: 4000C
A13: 11600 | B13: 미수수익 | C13: 미수수익 | D13: ='TB'!E8 -> 100032877 | E13: ='TB'!F8 -> 3528767 | F13: ='TB'!G8 -> 0 | G13: =D13+E13-F13 -> 103561644 | H13: ='TB'!I8 -> 109002740 | I13: =G13-H13 -> -5441096 | J13: =IF(H13=0,0,I13/ABS(H13)) -> -0.049917057 | K13: =IF(AND(ABS(I13)>=$K$3,OR(H13=0,ABS(J13)>=$K$4)),"설명 필요","") | L13: A3 | M13: 4000A
A14: 13300 | B14: 선급비용 | C14: 선급비용 | D14: ='TB'!E9 -> 0 | E14: ='TB'!F9 -> 45000000 | F14: ='TB'!G9 -> 0 | G14: =D14+E14-F14 -> 45000000 | H14: ='TB'!I9 -> 0 | I14: =G14-H14 -> 45000000 | J14: =IF(H14=0,0,I14/ABS(H14)) -> 0 | K14: =IF(AND(ABS(I14)>=$K$3,OR(H14=0,ABS(J14)>=$K$4)),"설명 필요","") | L14: A2 | M14: 4000D
A15: 13500 | B15: 부가세대급금 | C15: 부가세대급금 | D15: ='TB'!E10 -> 111738000 | E15: ='TB'!F10 -> 0 | F15: ='TB'!G10 -> 0 | G15: =D15+E15-F15 -> 111738000 | H15: ='TB'!I10 -> 151000000 | I15: =G15-H15 -> -39262000 | J15: =IF(H15=0,0,I15/ABS(H15)) -> -0.26001325 | K15: =IF(AND(ABS(I15)>=$K$3,OR(H15=0,ABS(J15)>=$K$4)),"설명 필요","") | M15: 4000D
A16: 13600 | B16: 선납세금 | C16: 당기법인세자산 | D16: ='TB'!E11 -> 18609360 | E16: ='TB'!F11 -> 0 | F16: ='TB'!G11 -> 0 | G16: =D16+E16-F16 -> 18609360 | H16: ='TB'!I11 -> 0 | I16: =G16-H16 -> 18609360 | J16: =IF(H16=0,0,I16/ABS(H16)) -> 0 | K16: =IF(AND(ABS(I16)>=$K$3,OR(H16=0,ABS(J16)>=$K$4)),"설명 필요","") | M16: 4000T
B17: Ⅱ. 비유동자산 | C17: 비유동자산 | D17: =SUM(D18,D22,D27,D30) -> 2655573220 | E17: =SUM(E18,E22,E27,E30) -> 1180000000 | F17: =SUM(F18,F22,F27,F30) -> 1180000000 | G17: =SUM(G18,G22,G27,G30) -> 2655573220 | H17: =SUM(H18,H22,H27,H30) -> 2969783534 | I17: =G17-H17 -> -314210314 | J17: =IF(H17=0,0,I17/ABS(H17)) -> -0.10580243
B18: (1) 투자자산 | C18: 투자자산 | D18: =SUM(D19,D20,D21) -> 1240000000 | E18: =SUM(E19,E20,E21) -> 1180000000 | F18: =SUM(F19,F20,F21) -> 1180000000 | G18: =SUM(G19,G20,G21) -> 1240000000 | H18: =SUM(H19,H20,H21) -> 1240000000 | I18: =G18-H18 -> 0 | J18: =IF(H18=0,0,I18/ABS(H18)) -> 0
A19: 17900 | B19: 장기대여금 | C19: 장기대여금 | D19: ='TB'!E14 -> 60000000 | E19: ='TB'!F14 -> 0 | F19: ='TB'!G14 -> 0 | G19: =D19+E19-F19 -> 60000000 | H19: ='TB'!I14 -> 60000000 | I19: =G19-H19 -> 0 | J19: =IF(H19=0,0,I19/ABS(H19)) -> 0 | K19: =IF(AND(ABS(I19)>=$K$3,OR(H19=0,ABS(J19)>=$K$4)),"설명 필요","") | M19: 4000F
A20: 18000 | B20: 지분법적용투자주식 | C20: 지분법적용투자주식 | D20: ='TB'!E13 -> 0 | E20: ='TB'!F13 -> 1180000000 | F20: ='TB'!G13 -> 0 | G20: =D20+E20-F20 -> 1180000000 | H20: ='TB'!I13 -> 1180000000 | I20: =G20-H20 -> 0 | J20: =IF(H20=0,0,I20/ABS(H20)) -> 0 | K20: =IF(AND(ABS(I20)>=$K$3,OR(H20=0,ABS(J20)>=$K$4)),"설명 필요","") | L20: A4 | M20: 4000F
A21: 17800 | B21: 투자유가증권 | C21: 지분법적용투자주식 | D21: ='TB'!E12 -> 1180000000 | E21: ='TB'!F12 -> 0 | F21: ='TB'!G12 -> 1180000000 | G21: =D21+E21-F21 -> 0 | H21: ='TB'!I12 -> 0 | I21: =G21-H21 -> 0 | J21: =IF(H21=0,0,I21/ABS(H21)) -> 0 | K21: =IF(AND(ABS(I21)>=$K$3,OR(H21=0,ABS(J21)>=$K$4)),"설명 필요","") | L21: A4 | M21: 4000F
B22: (2) 유형자산 | C22: 유형자산 | D22: =SUM(D23,D24,D25,D26) -> 875189879 | E22: =SUM(E23,E24,E25,E26) -> 0 | F22: =SUM(F23,F24,F25,F26) -> 0 | G22: =SUM(G23,G24,G25,G26) -> 875189879 | H22: =SUM(H23,H24,H25,H26) -> 1198400197 | I22: =G22-H22 -> -323210318 | J22: =IF(H22=0,0,I22/ABS(H22)) -> -0.26970149
A23: 21200 | B23: 비품 | C23: 비품 | D23: ='TB'!E15 -> 1245000000 | E23: ='TB'!F15 -> 0 | F23: ='TB'!G15 -> 0 | G23: =D23+E23-F23 -> 1245000000 | H23: ='TB'!I15 -> 1130900000 | I23: =G23-H23 -> 114100000 | J23: =IF(H23=0,0,I23/ABS(H23)) -> 0.10089309 | K23: =IF(AND(ABS(I23)>=$K$3,OR(H23=0,ABS(J23)>=$K$4)),"설명 필요","") -> 설명 필요 | M23: 4000G
A24: 21300 | B24: 감가상각누계액 | C24: 감가상각누계액(비품) | D24: ='TB'!E16 -> -771043482 | E24: ='TB'!F16 -> 0 | F24: ='TB'!G16 -> 0 | G24: =D24+E24-F24 -> -771043482 | H24: ='TB'!I16 -> -493333152 | I24: =G24-H24 -> -277710330 | J24: =IF(H24=0,0,I24/ABS(H24)) -> -0.56292655 | K24: =IF(AND(ABS(I24)>=$K$3,OR(H24=0,ABS(J24)>=$K$4)),"설명 필요","") -> 설명 필요 | M24: 4000G
A25: 22100 | B25: 시설장치 | C25: 시설장치 | D25: ='TB'!E17 -> 798000000 | E25: ='TB'!F17 -> 0 | F25: ='TB'!G17 -> 0 | G25: =D25+E25-F25 -> 798000000 | H25: ='TB'!I17 -> 798000000 | I25: =G25-H25 -> 0 | J25: =IF(H25=0,0,I25/ABS(H25)) -> 0 | K25: =IF(AND(ABS(I25)>=$K$3,OR(H25=0,ABS(J25)>=$K$4)),"설명 필요","") | M25: 4000G
A26: 22200 | B26: 감가상각누계액 | C26: 감가상각누계액(시설장치) | D26: ='TB'!E18 -> -396766639 | E26: ='TB'!F18 -> 0 | F26: ='TB'!G18 -> 0 | G26: =D26+E26-F26 -> -396766639 | H26: ='TB'!I18 -> -237166651 | I26: =G26-H26 -> -159599988 | J26: =IF(H26=0,0,I26/ABS(H26)) -> -0.67294448 | K26: =IF(AND(ABS(I26)>=$K$3,OR(H26=0,ABS(J26)>=$K$4)),"설명 필요","") -> 설명 필요 | M26: 4000G
B27: (3) 무형자산 | C27: 무형자산 | D27: =SUM(D28,D29) -> 160383341 | E27: =SUM(E28,E29) -> 0 | F27: =SUM(F28,F29) -> 0 | G27: =SUM(G28,G29) -> 160383341 | H27: =SUM(H28,H29) -> 151383337 | I27: =G27-H27 -> 9000004 | J27: =IF(H27=0,0,I27/ABS(H27)) -> 0.059451748
A28: 24000 | B28: 소프트웨어 | C28: 소프트웨어 | D28: ='TB'!E19 -> 119200000 | E28: ='TB'!F19 -> 0 | F28: ='TB'!G19 -> 0 | G28: =D28+E28-F28 -> 119200000 | H28: ='TB'!I19 -> 104400000 | I28: =G28-H28 -> 14800000 | J28: =IF(H28=0,0,I28/ABS(H28)) -> 0.14176245 | K28: =IF(AND(ABS(I28)>=$K$3,OR(H28=0,ABS(J28)>=$K$4)),"설명 필요","") | M28: 4000H
A29: 23200 | B29: 산업재산권 | C29: 산업재산권 | D29: ='TB'!E20 -> 41183341 | E29: ='TB'!F20 -> 0 | F29: ='TB'!G20 -> 0 | G29: =D29+E29-F29 -> 41183341 | H29: ='TB'!I20 -> 46983337 | I29: =G29-H29 -> -5799996 | J29: =IF(H29=0,0,I29/ABS(H29)) -> -0.12344794 | K29: =IF(AND(ABS(I29)>=$K$3,OR(H29=0,ABS(J29)>=$K$4)),"설명 필요","") | M29: 4000H
B30: (4) 기타비유동자산 | C30: 기타비유동자산 | D30: =SUM(D31) -> 380000000 | E30: =SUM(E31) -> 0 | F30: =SUM(F31) -> 0 | G30: =SUM(G31) -> 380000000 | H30: =SUM(H31) -> 380000000 | I30: =G30-H30 -> 0 | J30: =IF(H30=0,0,I30/ABS(H30)) -> 0
A31: 18300 | B31: 임차보증금 | C31: 임차보증금 | D31: ='TB'!E21 -> 380000000 | E31: ='TB'!F21 -> 0 | F31: ='TB'!G21 -> 0 | G31: =D31+E31-F31 -> 380000000 | H31: ='TB'!I21 -> 380000000 | I31: =G31-H31 -> 0 | J31: =IF(H31=0,0,I31/ABS(H31)) -> 0 | K31: =IF(AND(ABS(I31)>=$K$3,OR(H31=0,ABS(J31)>=$K$4)),"설명 필요","") | M31: 4000F
B32: 자산총계 | D32: =D8+D17 -> 9336696251 | G32: =G8+G17 -> 9385225018 | H32: =H8+H17 -> 10414977845 | I32: =G32-H32 -> -1029752827 | J32: =IF(H32=0,0,I32/ABS(H32)) -> -0.098872301
A33: 부채
B34: Ⅰ. 유동부채 | C34: 유동부채 | D34: =SUM(D35,D36,D37,D38,D39,D40,D41) -> 3509993085 | E34: =SUM(E35,E36,E37,E38,E39,E40,E41) -> 0 | F34: =SUM(F35,F36,F37,F38,F39,F40,F41) -> 38400000 | G34: =SUM(G35,G36,G37,G38,G39,G40,G41) -> 3548393085 | H34: =SUM(H35,H36,H37,H38,H39,H40,H41) -> 3339351041 | I34: =G34-H34 -> 209042044 | J34: =IF(H34=0,0,I34/ABS(H34)) -> 0.062599601
A35: 25100 | B35: 외상매입금 | C35: 매입채무 | D35: =-'TB'!E22 -> 228536000 | E35: ='TB'!F22 -> 0 | F35: ='TB'!G22 -> 0 | G35: =D35-E35+F35 -> 228536000 | H35: =-'TB'!I22 -> 176000000 | I35: =G35-H35 -> 52536000 | J35: =IF(H35=0,0,I35/ABS(H35)) -> 0.2985 | K35: =IF(AND(ABS(I35)>=$K$3,OR(H35=0,ABS(J35)>=$K$4)),"설명 필요","") | M35: 4000AA
A36: 25300 | B36: 미지급금 | C36: 미지급금 | D36: =-'TB'!E23 -> 149096000 | E36: ='TB'!F23 -> 0 | F36: ='TB'!G23 -> 0 | G36: =D36-E36+F36 -> 149096000 | H36: =-'TB'!I23 -> 119600000 | I36: =G36-H36 -> 29496000 | J36: =IF(H36=0,0,I36/ABS(H36)) -> 0.24662207 | K36: =IF(AND(ABS(I36)>=$K$3,OR(H36=0,ABS(J36)>=$K$4)),"설명 필요","") | M36: 4000CC
A37: 25400 | B37: 예수금 | C37: 예수금 | D37: =-'TB'!E24 -> 188039650 | E37: ='TB'!F24 -> 0 | F37: ='TB'!G24 -> 0 | G37: =D37-E37+F37 -> 188039650 | H37: =-'TB'!I24 -> 151620000 | I37: =G37-H37 -> 36419650 | J37: =IF(H37=0,0,I37/ABS(H37)) -> 0.24020347 | K37: =IF(AND(ABS(I37)>=$K$3,OR(H37=0,ABS(J37)>=$K$4)),"설명 필요","") | M37: 4000CC
A38: 25500 | B38: 부가세예수금 | C38: 부가세예수금 | D38: =-'TB'!E25 -> 389788078 | E38: ='TB'!F25 -> 0 | F38: ='TB'!G25 -> 0 | G38: =D38-E38+F38 -> 389788078 | H38: =-'TB'!I25 -> 414939340 | I38: =G38-H38 -> -25151262 | J38: =IF(H38=0,0,I38/ABS(H38)) -> -0.060614311 | K38: =IF(AND(ABS(I38)>=$K$3,OR(H38=0,ABS(J38)>=$K$4)),"설명 필요","") | M38: 4000CC
A39: 25900 | B39: 선수금 | C39: 선수금 | D39: =-'TB'!E26 -> 554533357 | E39: ='TB'!F26 -> 0 | F39: ='TB'!G26 -> 0 | G39: =D39-E39+F39 -> 554533357 | H39: =-'TB'!I26 -> 477191701 | I39: =G39-H39 -> 77341656 | J39: =IF(H39=0,0,I39/ABS(H39)) -> 0.1620767 | K39: =IF(AND(ABS(I39)>=$K$3,OR(H39=0,ABS(J39)>=$K$4)),"설명 필요","") -> 설명 필요 | M39: 4000P
A40: 26200 | B40: 미지급비용 | C40: 미지급비용 | D40: =-'TB'!E28 -> 0 | E40: ='TB'!F28 -> 0 | F40: ='TB'!G28 -> 38400000 | G40: =D40-E40+F40 -> 38400000 | H40: =-'TB'!I28 -> 0 | I40: =G40-H40 -> 38400000 | J40: =IF(H40=0,0,I40/ABS(H40)) -> 0 | K40: =IF(AND(ABS(I40)>=$K$3,OR(H40=0,ABS(J40)>=$K$4)),"설명 필요","") | L40: A1 | M40: 4000CC
A41: 26000 | B41: 단기차입금 | C41: 단기차입금 | D41: =-'TB'!E27 -> 2000000000 | E41: ='TB'!F27 -> 0 | F41: ='TB'!G27 -> 0 | G41: =D41-E41+F41 -> 2000000000 | H41: =-'TB'!I27 -> 2000000000 | I41: =G41-H41 -> 0 | J41: =IF(H41=0,0,I41/ABS(H41)) -> 0 | K41: =IF(AND(ABS(I41)>=$K$3,OR(H41=0,ABS(J41)>=$K$4)),"설명 필요","") | M41: 4000BBDD
...

Sheet 손익계산서
A1: 정산표(손익계산서)
A2: 제7기 2024-12-31 · 단위: 원 · 계정 줄은 TB 시트를 연결했다(자산 · 비용은 차변, 부채 · 자본 · 수익은 대변을 +로 보인다). 판정: |증감| 이 수행중요성 이상이고 증감률이 10% 이상이면 「설명 필요」
K3: 판정 기준 금액 | L3: ='표지'!$C$17 -> 74925000
K4: 판정 기준 비율 | L4: 0.1
A6: 코드 | B6: 회사 계정과목 | C6: 공시용 계정과목 | D6: 분류 | E6: 회사 제시 | F6: 수정 차변 | G6: 수정 대변 | H6: Final | I6: 전기 Final | J6: 증감 | K6: 증감률 | L6: 판정 | M6: 수정분개 | N6: 관련 조서
B7: Ⅰ. 매출액 | C7: 매출액 | E7: =SUM(E8,E9) -> 9990547268 | F7: =SUM(F8,F9) -> 0 | G7: =SUM(G8,G9) -> 0 | H7: =SUM(H8,H9) -> 9990547268 | I7: =SUM(I8,I9) -> 8526408762 | J7: =H7-I7 -> 1464138506 | K7: =IF(I7=0,0,J7/ABS(I7)) -> 0.17171808
A8: 41501 | B8: 국내구독매출 | C8: 국내구독매출 | D8: rev | E8: =-'TB'!E35 -> 8175103384 | F8: ='TB'!F35 -> 0 | G8: ='TB'!G35 -> 0 | H8: =E8-F8+G8 -> 8175103384 | I8: =-'TB'!I35 -> 7008516131 | J8: =H8-I8 -> 1166587253 | K8: =IF(I8=0,0,J8/ABS(I8)) -> 0.16645282 | L8: =IF(AND(ABS(J8)>=$L$3,OR(I8=0,ABS(K8)>=$L$4)),"설명 필요","") -> 설명 필요 | N8: 4000P
A9: 41502 | B9: 해외구독매출 | C9: 해외구독매출 | D9: rev | E9: =-'TB'!E36 -> 1815443884 | F9: ='TB'!F36 -> 0 | G9: ='TB'!G36 -> 0 | H9: =E9-F9+G9 -> 1815443884 | I9: =-'TB'!I36 -> 1517892631 | J9: =H9-I9 -> 297551253 | K9: =IF(I9=0,0,J9/ABS(I9)) -> 0.19602918 | L9: =IF(AND(ABS(J9)>=$L$3,OR(I9=0,ABS(K9)>=$L$4)),"설명 필요","") -> 설명 필요 | N9: 4000P
B10: Ⅱ. 매출원가 | C10: 매출원가 | E10: =SUM(E11) -> 2363760000 | F10: =SUM(F11) -> 38400000 | G10: =SUM(G11) -> 0 | H10: =SUM(H11) -> 2402160000 | I10: =SUM(I11) -> 1973374440 | J10: =H10-I10 -> 428785560 | K10: =IF(I10=0,0,J10/ABS(I10)) -> 0.21728545
A11: 45200 | B11: 용역매출원가 | C11: 용역매출원가 | D11: cogs | E11: ='TB'!E37 -> 2363760000 | F11: ='TB'!F37 -> 38400000 | G11: ='TB'!G37 -> 0 | H11: =E11+F11-G11 -> 2402160000 | I11: ='TB'!I37 -> 1973374440 | J11: =H11-I11 -> 428785560 | K11: =IF(I11=0,0,J11/ABS(I11)) -> 0.21728545 | L11: =IF(AND(ABS(J11)>=$L$3,OR(I11=0,ABS(K11)>=$L$4)),"설명 필요","") -> 설명 필요 | M11: A1 | N11: 4000Q
B12: Ⅲ. 매출총이익 | E12: =E7-E10 -> 7626787268 | H12: =H7-H10 -> 7588387268 | I12: =I7-I10 -> 6553034322 | J12: =H12-I12 -> 1035352946 | K12: =IF(I12=0,0,J12/ABS(I12)) -> 0.15799596
B13: Ⅳ. 판매비와관리비 | C13: 판매비와관리비 | E13: =SUM(E14,E15,E16,E17,E18,E19,E20,E21,E22,E23,E24,E25,E26,E27,E28,E29,E30,E31,E32) -> 11939296577 | F13: =SUM(F14,F15,F16,F17,F18,F19,F20,F21,F22,F23,F24,F25,F26,F27,F28,F29,F30,F31,F32) -> 0 | G13: =SUM(G14,G15,G16,G17,G18,G19,G20,G21,G22,G23,G24,G25,G26,G27,G28,G29,G30,G31,G32) -> 45000000 | H13: =SUM(H14,H15,H16,H17,H18,H19,H20,H21,H22,H23,H24,H25,H26,H27,H28,H29,H30,H31,H32) -> 11894296577 | I13: =SUM(I14,I15,I16,I17,I18,I19,I20,I21,I22,I23,I24,I25,I26,I27,I28,I29,I30,I31,I32) -> 10115191863 | J13: =H13-I13 -> 1779104714 | K13: =IF(I13=0,0,J13/ABS(I13)) -> 0.17588443
A14: 80200 | B14: 직원급여 | C14: 급여 | D14: sga | E14: ='TB'!E38 -> 3609528000 | F14: ='TB'!F38 -> 0 | G14: ='TB'!G38 -> 0 | H14: =E14+F14-G14 -> 3609528000 | I14: ='TB'!I38 -> 3108525513 | J14: =H14-I14 -> 501002487 | K14: =IF(I14=0,0,J14/ABS(I14)) -> 0.16117046 | L14: =IF(AND(ABS(J14)>=$L$3,OR(I14=0,ABS(K14)>=$L$4)),"설명 필요","") -> 설명 필요 | N14: 4000EE
A15: 80300 | B15: 상여금 | C15: 상여금 | D15: sga | E15: ='TB'!E39 -> 240000000 | F15: ='TB'!F39 -> 0 | G15: ='TB'!G39 -> 0 | H15: =E15+F15-G15 -> 240000000 | I15: ='TB'!I39 -> 186000000 | J15: =H15-I15 -> 54000000 | K15: =IF(I15=0,0,J15/ABS(I15)) -> 0.29032258 | L15: =IF(AND(ABS(J15)>=$L$3,OR(I15=0,ABS(K15)>=$L$4)),"설명 필요","") | N15: 4000EE
A16: 80600 | B16: 퇴직급여 | C16: 퇴직급여 | D16: sga | E16: ='TB'!E40 -> 300793996 | F16: ='TB'!F40 -> 0 | G16: ='TB'!G40 -> 0 | H16: =E16+F16-G16 -> 300793996 | I16: ='TB'!I40 -> 259043789 | J16: =H16-I16 -> 41750207 | K16: =IF(I16=0,0,J16/ABS(I16)) -> 0.16117046 | L16: =IF(AND(ABS(J16)>=$L$3,OR(I16=0,ABS(K16)>=$L$4)),"설명 필요","") | N16: 4000EE
A17: 81100 | B17: 복리후생비 | C17: 복리후생비 | D17: sga | E17: ='TB'!E41 -> 597765320 | F17: ='TB'!F41 -> 0 | G17: ='TB'!G41 -> 0 | H17: =E17+F17-G17 -> 597765320 | I17: ='TB'!I41 -> 504334600 | J17: =H17-I17 -> 93430720 | K17: =IF(I17=0,0,J17/ABS(I17)) -> 0.18525542 | L17: =IF(AND(ABS(J17)>=$L$3,OR(I17=0,ABS(K17)>=$L$4)),"설명 필요","") -> 설명 필요 | N17: 4000EE
A18: 81200 | B18: 여비교통비 | C18: 여비교통비 | D18: sga | E18: ='TB'!E42 -> 120960000 | F18: ='TB'!F42 -> 0 | G18: ='TB'!G42 -> 0 | H18: =E18+F18-G18 -> 120960000 | I18: ='TB'!I42 -> 99078336 | J18: =H18-I18 -> 21881664 | K18: =IF(I18=0,0,J18/ABS(I18)) -> 0.22085215 | L18: =IF(AND(ABS(J18)>=$L$3,OR(I18=0,ABS(K18)>=$L$4)),"설명 필요","") | N18: 4000EE
A19: 81300 | B19: 기업업무추진비 | C19: 기업업무추진비 | D19: sga | E19: ='TB'!E43 -> 60480000 | F19: ='TB'!F43 -> 0 | G19: ='TB'!G43 -> 0 | H19: =E19+F19-G19 -> 60480000 | I19: ='TB'!I43 -> 50004864 | J19: =H19-I19 -> 10475136 | K19: =IF(I19=0,0,J19/ABS(I19)) -> 0.20948234 | L19: =IF(AND(ABS(J19)>=$L$3,OR(I19=0,ABS(K19)>=$L$4)),"설명 필요","") | N19: 4000EE
A20: 81400 | B20: 통신비 | C20: 통신비 | D20: sga | E20: ='TB'!E44 -> 60480000 | F20: ='TB'!F44 -> 0 | G20: ='TB'!G44 -> 0 | H20: =E20+F20-G20 -> 60480000 | I20: ='TB'!I44 -> 54643680 | J20: =H20-I20 -> 5836320 | K20: =IF(I20=0,0,J20/ABS(I20)) -> 0.10680686 | L20: =IF(AND(ABS(J20)>=$L$3,OR(I20=0,ABS(K20)>=$L$4)),"설명 필요","") | N20: 4000EE
A21: 81700 | B21: 세금과공과 | C21: 세금과공과 | D21: sga | E21: ='TB'!E45 -> 330632820 | F21: ='TB'!F45 -> 0 | G21: ='TB'!G45 -> 0 | H21: =E21+F21-G21 -> 330632820 | I21: ='TB'!I45 -> 282988630 | J21: =H21-I21 -> 47644190 | K21: =IF(I21=0,0,J21/ABS(I21)) -> 0.16836079 | L21: =IF(AND(ABS(J21)>=$L$3,OR(I21=0,ABS(K21)>=$L$4)),"설명 필요","") | N21: 4000EE
A22: 81800 | B22: 감가상각비 | C22: 감가상각비 | D22: sga | E22: ='TB'!E46 -> 437310318 | F22: ='TB'!F46 -> 0 | G22: ='TB'!G46 -> 0 | H22: =E22+F22-G22 -> 437310318 | I22: ='TB'!I46 -> 385458225 | J22: =H22-I22 -> 51852093 | K22: =IF(I22=0,0,J22/ABS(I22)) -> 0.13452066 | L22: =IF(AND(ABS(J22)>=$L$3,OR(I22=0,ABS(K22)>=$L$4)),"설명 필요","") | N22: 4000EE
A23: 81900 | B23: 지급임차료 | C23: 지급임차료 | D23: sga | E23: ='TB'!E47 -> 410160000 | F23: ='TB'!F47 -> 0 | G23: ='TB'!G47 -> 0 | H23: =E23+F23-G23 -> 410160000 | I23: ='TB'!I47 -> 386160000 | J23: =H23-I23 -> 24000000 | K23: =IF(I23=0,0,J23/ABS(I23)) -> 0.062150404 | L23: =IF(AND(ABS(J23)>=$L$3,OR(I23=0,ABS(K23)>=$L$4)),"설명 필요","") | N23: 4000EE
A24: 82100 | B24: 보험료 | C24: 보험료 | D24: sga | E24: ='TB'!E48 -> 152379460 | F24: ='TB'!F48 -> 0 | G24: ='TB'!G48 -> 0 | H24: =E24+F24-G24 -> 152379460 | I24: ='TB'!I48 -> 134794870 | J24: =H24-I24 -> 17584590 | K24: =IF(I24=0,0,J24/ABS(I24)) -> 0.13045445 | L24: =IF(AND(ABS(J24)>=$L$3,OR(I24=0,ABS(K24)>=$L$4)),"설명 필요","") | N24: 4000EE
A25: 82200 | B25: 차량유지비 | C25: 차량유지비 | D25: sga | E25: ='TB'!E49 -> 50400000 | F25: ='TB'!F49 -> 0 | G25: ='TB'!G49 -> 0 | H25: =E25+F25-G25 -> 50400000 | I25: ='TB'!I49 -> 46000080 | J25: =H25-I25 -> 4399920 | K25: =IF(I25=0,0,J25/ABS(I25)) -> 0.095650268 | L25: =IF(AND(ABS(J25)>=$L$3,OR(I25=0,ABS(K25)>=$L$4)),"설명 필요","") | N25: 4000EE
... A27: 83000 | B27: 소모품비 | C27: 소모품비 | D27: sga | E27: ='TB'!E51 -> 80640000 | F27: ='TB'!F51 -> 0 | G27: ='TB'!G51 -> 0 | H27: =E27+F27-G27 -> 80640000 | I27: ='TB'!I51 -> 68156928 | J27: =H27-I27 -> 12483072 | K27: =IF(I27=0,0,J27/ABS(I27)) -> 0.18315192 | L27: =IF(AND(ABS(J27)>=$L$3,OR(I27=0,ABS(K27)>=$L$4)),"설명 필요","") | N27: 4000EE
A28: 83100 | B28: 지급수수료 | C28: 지급수수료 | D28: sga | E28: ='TB'!E52 -> 506849667 | F28: ='TB'!F52 -> 0 | G28: ='TB'!G52 -> 45000000 | H28: =E28+F28-G28 -> 461849667 | I28: ='TB'!I52 -> 377515917 | J28: =H28-I28 -> 84333750 | K28: =IF(I28=0,0,J28/ABS(I28)) -> 0.22339124 | L28: =IF(AND(ABS(J28)>=$L$3,OR(I28=0,ABS(K28)>=$L$4)),"설명 필요","") -> 설명 필요 | M28: A2 | N28: 4000EE
A29: 83300 | B29: 광고선전비 | C29: 광고선전비 | D29: sga | E29: ='TB'!E53 -> 692400000 | F29: ='TB'!F53 -> 0 | G29: ='TB'!G53 -> 0 | H29: =E29+F29-G29 -> 692400000 | I29: ='TB'!I53 -> 532594080 | J29: =H29-I29 -> 159805920 | K29: =IF(I29=0,0,J29/ABS(I29)) -> 0.300052 | L29: =IF(AND(ABS(J29)>=$L$3,OR(I29=0,ABS(K29)>=$L$4)),"설명 필요","") -> 설명 필요 | N29: 4000EE
A30: 84000 | B30: 무형자산상각비 | C30: 무형자산상각비 | D30: sga | E30: ='TB'!E54 -> 38999996 | F30: ='TB'!F54 -> 0 | G30: ='TB'!G54 -> 0 | H30: =E30+F30-G30 -> 38999996 | I30: ='TB'!I54 -> 32016663 | J30: =H30-I30 -> 6983333 | K30: =IF(I30=0,0,J30/ABS(I30)) -> 0.21811558 | L30: =IF(AND(ABS(J30)>=$L$3,OR(I30=0,ABS(K30)>=$L$4)),"설명 필요","") | N30: 4000EE
A31: 84300 | B31: 경상연구개발비 | C31: 경상연구개발비 | D31: sga | E31: ='TB'!E55 -> 4049357000 | F31: ='TB'!F55 -> 0 | G31: ='TB'!G55 -> 0 | H31: =E31+F31-G31 -> 4049357000 | I31: ='TB'!I55 -> 3455316328 | J31: =H31-I31 -> 594040672 | K31: =IF(I31=0,0,J31/ABS(I31)) -> 0.17192078 | L31: =IF(AND(ABS(J31)>=$L$3,OR(I31=0,ABS(K31)>=$L$4)),"설명 필요","") -> 설명 필요 | N31: 4000EE
A32: 85300 | B32: 주식보상비용 | C32: 주식보상비용 | D32: sga | E32: ='TB'!E56 -> 180000000 | F32: ='TB'!F56 -> 0 | G32: ='TB'!G56 -> 0 | H32: =E32+F32-G32 -> 180000000 | I32: ='TB'!I56 -> 135000000 | J32: =H32-I32 -> 45000000 | K32: =IF(I32=0,0,J32/ABS(I32)) -> 0.33333333 | L32: =IF(AND(ABS(J32)>=$L$3,OR(I32=0,ABS(K32)>=$L$4)),"설명 필요","") | N32: 4000EE
B33: Ⅴ. 영업손실 | E33: =E12-E13 -> -4312509309 | H33: =H12-H13 -> -4305909309 | I33: =I12-I13 -> -3562157541 | J33: =H33-I33 -> -743751768 | K33: =IF(I33=0,0,J33/ABS(I33)) -> -0.2087925
B34: Ⅵ. 영업외수익 | C34: 영업외수익 | E34: =SUM(E35,E36,E37) -> 125560260 | F34: =SUM(F35,F36,F37) -> 0 | G34: =SUM(G35,G36,G37) -> 3528767 | H34: =SUM(H35,H36,H37) -> 129089027 | I34: =SUM(I35,I36,I37) -> 115797660 | J34: =H34-I34 -> 13291367 | K34: =IF(I34=0,0,J34/ABS(I34)) -> 0.11478096
A35: 90100 | B35: 이자수익 | C35: 이자수익 | D35: nonop_in | E35: =-'TB'!E57 -> 111870137 | F35: ='TB'!F57 -> 0 | G35: ='TB'!G57 -> 3528767 | H35: =E35-F35+G35 -> 115398904 | I35: =-'TB'!I57 -> 111187252 | J35: =H35-I35 -> 4211652 | K35: =IF(I35=0,0,J35/ABS(I35)) -> 0.037878911 | L35: =IF(AND(ABS(J35)>=$L$3,OR(I35=0,ABS(K35)>=$L$4)),"설명 필요","") | M35: A3 | N35: 4000A
A36: 90700 | B36: 외환차익 | C36: 외환차익 | D36: nonop_in | E36: =-'TB'!E58 -> 921967 | F36: ='TB'!F58 -> 0 | G36: ='TB'!G58 -> 0 | H36: =E36-F36+G36 -> 921967 | I36: =-'TB'!I58 -> 1483920 | J36: =H36-I36 -> -561953 | K36: =IF(I36=0,0,J36/ABS(I36)) -> -0.37869494 | L36: =IF(AND(ABS(J36)>=$L$3,OR(I36=0,ABS(K36)>=$L$4)),"설명 필요","") | N36: 4000A
A37: 91000 | B37: 외화환산이익 | C37: 외화환산이익 | D37: nonop_in | E37: =-'TB'!E59 -> 12768156 | F37: ='TB'!F59 -> 0 | G37: ='TB'!G59 -> 0 | H37: =E37-F37+G37 -> 12768156 | I37: =-'TB'!I59 -> 3126488 | J37: =H37-I37 -> 9641668 | K37: =IF(I37=0,0,J37/ABS(I37)) -> 3.0838653 | L37: =IF(AND(ABS(J37)>=$L$3,OR(I37=0,ABS(K37)>=$L$4)),"설명 필요","") | N37: 4000A
B38: Ⅶ. 영업외비용 | C38: 영업외비용 | E38: =SUM(E39,E40) -> 241974589 | F38: =SUM(F39,F40) -> 0 | G38: =SUM(G39,G40) -> 0 | H38: =SUM(H39,H40) -> 241974589 | I38: =SUM(I39,I40) -> 173861370 | J38: =H38-I38 -> 68113219 | K38: =IF(I38=0,0,J38/ABS(I38)) -> 0.39176741
A39: 93100 | B39: 이자비용 | C39: 이자비용 | D39: nonop_out | E39: ='TB'!E60 -> 240000000 | F39: ='TB'!F60 -> 0 | G39: ='TB'!G60 -> 0 | H39: =E39+F39-G39 -> 240000000 | I39: ='TB'!I60 -> 171000000 | J39: =H39-I39 -> 69000000 | K39: =IF(I39=0,0,J39/ABS(I39)) -> 0.40350877 | L39: =IF(AND(ABS(J39)>=$L$3,OR(I39=0,ABS(K39)>=$L$4)),"설명 필요","") | N39: 4000BBDD
A40: 93200 | B40: 외환차손 | C40: 외환차손 | D40: nonop_out | E40: ='TB'!E61 -> 1974589 | F40: ='TB'!F61 -> 0 | G40: ='TB'!G61 -> 0 | H40: =E40+F40-G40 -> 1974589 | I40: ='TB'!I61 -> 2861370 | J40: =H40-I40 -> -886781 | K40: =IF(I40=0,0,J40/ABS(I40)) -> -0.30991483 | L40: =IF(AND(ABS(J40)>=$L$3,OR(I40=0,ABS(K40)>=$L$4)),"설명 필요","") | N40: 4000A
B41: Ⅷ. 법인세비용차감전순손실 | E41: =E33+E34-E38 -> -4428923638 | H41: =H33+H34-H38 -> -4418794871 | I41: =I33+I34-I38 -> -3620221251 | J41: =H41-I41 -> -798573620 | K41: =IF(I41=0,0,J41/ABS(I41)) -> -0.22058697
B42: Ⅸ. 법인세비용 | C42: 법인세비용 | E42: =SUM(0) -> 0 | F42: =SUM(0) -> 0 | G42: =SUM(0) -> 0 | H42: =SUM(0) -> 0 | I42: =SUM(0) -> 0 | J42: =H42-I42 -> 0 | K42: =IF(I42=0,0,J42/ABS(I42)) -> 0
...

Sheet AJE
B1: 감사 수정분개(AJE) · 재분류(RJE) · 제7기 2024-12-31
B2: 한 줄에 계정 하나. TB 시트의 수정 차변 · 대변이 이 시트의 계정코드(I · J 열)로 SUMIFS 한다. 손익 영향은 당기순이익 기준(이익 +).
B4: No. | C4: 구분 | D4: 내역 | E4: 차변 | G4: 대변 | I4: 차변 코드 | J4: 대변 코드 | K4: 손익 영향 | L4: 근거 | M4: 관련 조서 | N4: 회사 반영
E5: 계정과목 | F5: 금액 | G5: 계정과목 | H5: 금액
B6: 1 | C6: AJE | D6: 12월 클라우드 서버 추가 사용분(1월 청구) 미지급비용 계상 | E6: 용역매출원가 | F6: 38400000 | I6: 45200 | K6: =IF(N(I6)>=40000,-N(F6),0)+IF(N(J6)>=40000,N(H6),0) -> -38400000 | L6: 1월 청구서(구름서버) 사용 기간 2024-12 · 결산일 후 지급 검토 | M6: 4000AA | N6: 예(2024 장부)
G7: 미지급비용 | H7: 38400000 | J7: 26200 | K7: =IF(N(I7)>=40000,-N(F7),0)+IF(N(J7)>=40000,N(H7),0) -> 0
B8: 2 | C8: AJE | D8: 연간 SaaS 라이선스 선지급분 선급비용 대체 | E8: 선급비용 | F8: 45000000 | I8: 13300 | K8: =IF(N(I8)>=40000,-N(F8),0)+IF(N(J8)>=40000,N(H8),0) -> 0 | L8: 클라우드툴즈 연간 라이선스 계약서(2024-12 ~ 2025-11) | M8: 4000D | N8: 예(2024 장부)
G9: 지급수수료 | H9: 45000000 | J9: 83100 | K9: =IF(N(I9)>=40000,-N(F9),0)+IF(N(J9)>=40000,N(H9),0) -> 45000000
B10: 3 | C10: AJE | D10: 정기예금 미수이자 추가 계상(회사가 월할로 계산한 차이) | E10: 미수수익 | F10: 3528767 | I10: 11600 | K10: =IF(N(I10)>=40000,-N(F10),0)+IF(N(J10)>=40000,N(H10),0) -> 0 | L10: 정기예금 증서(3.6%, 2024-01-16 ~ 2025-01-15) 일할 계산 350일 | M10: 4000A | N10: 예(2024 장부)
G11: 이자수익 | H11: 3528767 | J11: 90100 | K11: =IF(N(I11)>=40000,-N(F11),0)+IF(N(J11)>=40000,N(H11),0) -> 3528767
B12: 4 | C12: RJE | D12: 투자유가증권(미국 자회사 100%)을 지분법적용투자주식으로 표시 | E12: 지분법적용투자주식 | F12: 1180000000 | I12: 18000 | K12: =IF(N(I12)>=40000,-N(F12),0)+IF(N(J12)>=40000,N(H12),0) -> 0 | L12: 도담소프트 USA Inc. 주주명부 · 해외직접투자 신고서 | M12: 4000F | N12: 아니오(공시 재분류)
G13: 투자유가증권 | H13: 1180000000 | J13: 17800 | K13: =IF(N(I13)>=40000,-N(F13),0)+IF(N(J13)>=40000,N(H13),0) -> 0
B14: 합계 | F14: =SUM(F6:F13) -> 1266928767 | H14: =SUM(H6:H13) -> 1266928767 | K14: =SUM(K6:K13) -> 10128767 | N14: =IF(F14=H14,"OK","차대 불일치") -> OK
B17: 당기순손익 대사
D18: 회사 제시 당기순손익 | F18: ='손익계산서'!E43 -> -4428923638
D19: 수정분개 손익 영향 | F19: =K14 -> 10128767
D20: 감사 후 당기순손익 | F20: =F18+F19 -> -4418794871
D21: 손익계산서 Final | F21: ='손익계산서'!H43 -> -4418794871
D22: 차이 | F22: =IF(ROUND(F20-F21,0)=0,"OK","차이 확인") -> OK

Sheet 공시용BS
B1: 재무상태표(공시용)
B2: 제7(당)기 2024-12-31 현재 · 제6(전)기 2023-12-31 현재 · 단위: 원 · 정산표를 공시용 계정과목(H 열)으로 SUMIF
A4: 구분 | B4: 과목 | C4: 주석 | D4: 당기(회사제시) | E4: 당기(최종) | F4: 전기(최종) | G4: 증감 | H4: 표시과목(정산표 연결)
B5: 자산
A6: BS | B6: Ⅰ. 유동자산 | D6: =SUM(D7) -> 6681123031 | E6: =SUM(E7) -> 6729651798 | F6: =SUM(F7) -> 7445194311 | G6: =E6-F6 -> -715542513 | H6: 유동자산
A7: BS | B7: (1) 당좌자산 | D7: =SUM(D8,D9,D10,D11,D12,D13,D14) -> 6681123031 | E7: =SUM(E8,E9,E10,E11,E12,E13,E14) -> 6729651798 | F7: =SUM(F8,F9,F10,F11,F12,F13,F14) -> 7445194311 | G7: =E7-F7 -> -715542513 | H7: 당좌자산
A8: BS | B8: 현금및현금성자산 | C8: 3,15 | D8: =SUMIF('재무상태표'!$C$7:$C$57,$H8,'재무상태표'!$D$7:$D$57) -> 2769582606 | E8: =SUMIF('재무상태표'!$C$7:$C$57,$H8,'재무상태표'!$G$7:$G$57) -> 2769582606 | F8: =SUMIF('재무상태표'!$C$7:$C$57,$H8,'재무상태표'!$H$7:$H$57) -> 3645038600 | G8: =E8-F8 -> -875455994 | H8: 현금및현금성자산
A9: BS | B9: 단기금융상품 | C9: 4 | D9: =SUMIF('재무상태표'!$C$7:$C$57,$H9,'재무상태표'!$D$7:$D$57) -> 3000000000 | E9: =SUMIF('재무상태표'!$C$7:$C$57,$H9,'재무상태표'!$G$7:$G$57) -> 3000000000 | F9: =SUMIF('재무상태표'!$C$7:$C$57,$H9,'재무상태표'!$H$7:$H$57) -> 3000000000 | G9: =E9-F9 -> 0 | H9: 단기금융상품
A10: BS | B10: 매출채권 | C10: 5,15 | D10: =SUMIF('재무상태표'!$C$7:$C$57,$H10,'재무상태표'!$D$7:$D$57) -> 681160188 | E10: =SUMIF('재무상태표'!$C$7:$C$57,$H10,'재무상태표'!$G$7:$G$57) -> 681160188 | F10: =SUMIF('재무상태표'!$C$7:$C$57,$H10,'재무상태표'!$H$7:$H$57) -> 540152971 | G10: =E10-F10 -> 141007217 | H10: 매출채권
A11: BS | B11: 미수수익 | D11: =SUMIF('재무상태표'!$C$7:$C$57,$H11,'재무상태표'!$D$7:$D$57) -> 100032877 | E11: =SUMIF('재무상태표'!$C$7:$C$57,$H11,'재무상태표'!$G$7:$G$57) -> 103561644 | F11: =SUMIF('재무상태표'!$C$7:$C$57,$H11,'재무상태표'!$H$7:$H$57) -> 109002740 | G11: =E11-F11 -> -5441096 | H11: 미수수익
A12: BS | B12: 선급비용 | D12: =SUMIF('재무상태표'!$C$7:$C$57,$H12,'재무상태표'!$D$7:$D$57) -> 0 | E12: =SUMIF('재무상태표'!$C$7:$C$57,$H12,'재무상태표'!$G$7:$G$57) -> 45000000 | F12: =SUMIF('재무상태표'!$C$7:$C$57,$H12,'재무상태표'!$H$7:$H$57) -> 0 | G12: =E12-F12 -> 45000000 | H12: 선급비용
A13: BS | B13: 부가세대급금 | D13: =SUMIF('재무상태표'!$C$7:$C$57,$H13,'재무상태표'!$D$7:$D$57) -> 111738000 | E13: =SUMIF('재무상태표'!$C$7:$C$57,$H13,'재무상태표'!$G$7:$G$57) -> 111738000 | F13: =SUMIF('재무상태표'!$C$7:$C$57,$H13,'재무상태표'!$H$7:$H$57) -> 151000000 | G13: =E13-F13 -> -39262000 | H13: 부가세대급금
A14: BS | B14: 당기법인세자산 | C14: 16 | D14: =SUMIF('재무상태표'!$C$7:$C$57,$H14,'재무상태표'!$D$7:$D$57) -> 18609360 | E14: =SUMIF('재무상태표'!$C$7:$C$57,$H14,'재무상태표'!$G$7:$G$57) -> 18609360 | F14: =SUMIF('재무상태표'!$C$7:$C$57,$H14,'재무상태표'!$H$7:$H$57) -> 0 | G14: =E14-F14 -> 18609360 | H14: 당기법인세자산
A15: BS | B15: Ⅱ. 비유동자산 | D15: =SUM(D16,D19,D24,D27) -> 2655573220 | E15: =SUM(E16,E19,E24,E27) -> 2655573220 | F15: =SUM(F16,F19,F24,F27) -> 2969783534 | G15: =E15-F15 -> -314210314 | H15: 비유동자산
A16: BS | B16: (1) 투자자산 | D16: =SUM(D17,D18) -> 1240000000 | E16: =SUM(E17,E18) -> 1240000000 | F16: =SUM(F17,F18) -> 1240000000 | G16: =E16-F16 -> 0 | H16: 투자자산
A17: BS | B17: 장기대여금 | C17: 6 | D17: =SUMIF('재무상태표'!$C$7:$C$57,$H17,'재무상태표'!$D$7:$D$57) -> 60000000 | E17: =SUMIF('재무상태표'!$C$7:$C$57,$H17,'재무상태표'!$G$7:$G$57) -> 60000000 | F17: =SUMIF('재무상태표'!$C$7:$C$57,$H17,'재무상태표'!$H$7:$H$57) -> 60000000 | G17: =E17-F17 -> 0 | H17: 장기대여금
A18: BS | B18: 지분법적용투자주식 | C18: 7,18 | D18: =SUMIF('재무상태표'!$C$7:$C$57,$H18,'재무상태표'!$D$7:$D$57) -> 1180000000 | E18: =SUMIF('재무상태표'!$C$7:$C$57,$H18,'재무상태표'!$G$7:$G$57) -> 1180000000 | F18: =SUMIF('재무상태표'!$C$7:$C$57,$H18,'재무상태표'!$H$7:$H$57) -> 1180000000 | G18: =E18-F18 -> 0 | H18: 지분법적용투자주식
A19: BS | B19: (2) 유형자산 | C19: 8,17 | D19: =SUM(D20,D21,D22,D23) -> 875189879 | E19: =SUM(E20,E21,E22,E23) -> 875189879 | F19: =SUM(F20,F21,F22,F23) -> 1198400197 | G19: =E19-F19 -> -323210318 | H19: 유형자산
A20: BS | B20: 비품 | D20: =SUMIF('재무상태표'!$C$7:$C$57,$H20,'재무상태표'!$D$7:$D$57) -> 1245000000 | E20: =SUMIF('재무상태표'!$C$7:$C$57,$H20,'재무상태표'!$G$7:$G$57) -> 1245000000 | F20: =SUMIF('재무상태표'!$C$7:$C$57,$H20,'재무상태표'!$H$7:$H$57) -> 1130900000 | G20: =E20-F20 -> 114100000 | H20: 비품
A21: BS | B21: 감가상각누계액 | D21: =SUMIF('재무상태표'!$C$7:$C$57,$H21,'재무상태표'!$D$7:$D$57) -> -771043482 | E21: =SUMIF('재무상태표'!$C$7:$C$57,$H21,'재무상태표'!$G$7:$G$57) -> -771043482 | F21: =SUMIF('재무상태표'!$C$7:$C$57,$H21,'재무상태표'!$H$7:$H$57) -> -493333152 | G21: =E21-F21 -> -277710330 | H21: 감가상각누계액(비품)
A22: BS | B22: 시설장치 | D22: =SUMIF('재무상태표'!$C$7:$C$57,$H22,'재무상태표'!$D$7:$D$57) -> 798000000 | E22: =SUMIF('재무상태표'!$C$7:$C$57,$H22,'재무상태표'!$G$7:$G$57) -> 798000000 | F22: =SUMIF('재무상태표'!$C$7:$C$57,$H22,'재무상태표'!$H$7:$H$57) -> 798000000 | G22: =E22-F22 -> 0 | H22: 시설장치
A23: BS | B23: 감가상각누계액 | D23: =SUMIF('재무상태표'!$C$7:$C$57,$H23,'재무상태표'!$D$7:$D$57) -> -396766639 | E23: =SUMIF('재무상태표'!$C$7:$C$57,$H23,'재무상태표'!$G$7:$G$57) -> -396766639 | F23: =SUMIF('재무상태표'!$C$7:$C$57,$H23,'재무상태표'!$H$7:$H$57) -> -237166651 | G23: =E23-F23 -> -159599988 | H23: 감가상각누계액(시설장치)
A24: BS | B24: (3) 무형자산 | C24: 9 | D24: =SUM(D25,D26) -> 160383341 | E24: =SUM(E25,E26) -> 160383341 | F24: =SUM(F25,F26) -> 151383337 | G24: =E24-F24 -> 9000004 | H24: 무형자산
A25: BS | B25: 소프트웨어 | D25: =SUMIF('재무상태표'!$C$7:$C$57,$H25,'재무상태표'!$D$7:$D$57) -> 119200000 | E25: =SUMIF('재무상태표'!$C$7:$C$57,$H25,'재무상태표'!$G$7:$G$57) -> 119200000 | F25: =SUMIF('재무상태표'!$C$7:$C$57,$H25,'재무상태표'!$H$7:$H$57) -> 104400000 | G25: =E25-F25 -> 14800000 | H25: 소프트웨어
A26: BS | B26: 산업재산권 | D26: =SUMIF('재무상태표'!$C$7:$C$57,$H26,'재무상태표'!$D$7:$D$57) -> 41183341 | E26: =SUMIF('재무상태표'!$C$7:$C$57,$H26,'재무상태표'!$G$7:$G$57) -> 41183341 | F26: =SUMIF('재무상태표'!$C$7:$C$57,$H26,'재무상태표'!$H$7:$H$57) -> 46983337 | G26: =E26-F26 -> -5799996 | H26: 산업재산권
A27: BS | B27: (4) 기타비유동자산 | D27: =SUM(D28) -> 380000000 | E27: =SUM(E28) -> 380000000 | F27: =SUM(F28) -> 380000000 | G27: =E27-F27 -> 0 | H27: 기타비유동자산
A28: BS | B28: 임차보증금 | C28: 17 | D28: =SUMIF('재무상태표'!$C$7:$C$57,$H28,'재무상태표'!$D$7:$D$57) -> 380000000 | E28: =SUMIF('재무상태표'!$C$7:$C$57,$H28,'재무상태표'!$G$7:$G$57) -> 380000000 | F28: =SUMIF('재무상태표'!$C$7:$C$57,$H28,'재무상태표'!$H$7:$H$57) -> 380000000 | G28: =E28-F28 -> 0 | H28: 임차보증금
A29: BS | B29: 자산총계 | D29: =D6+D15 -> 9336696251 | E29: =E6+E15 -> 9385225018 | F29: =F6+F15 -> 10414977845 | G29: =E29-F29 -> -1029752827 | H29: 자산총계
B30: 부채
A31: BS | B31: Ⅰ. 유동부채 | D31: =SUM(D32,D33,D34,D35,D36,D37,D38) -> 3509993085 | E31: =SUM(E32,E33,E34,E35,E36,E37,E38) -> 3548393085 | F31: =SUM(F32,F33,F34,F35,F36,F37,F38) -> 3339351041 | G31: =E31-F31 -> 209042044 | H31: 유동부채
A32: BS | B32: 매입채무 | D32: =SUMIF('재무상태표'!$C$7:$C$57,$H32,'재무상태표'!$D$7:$D$57) -> 228536000 | E32: =SUMIF('재무상태표'!$C$7:$C$57,$H32,'재무상태표'!$G$7:$G$57) -> 228536000 | F32: =SUMIF('재무상태표'!$C$7:$C$57,$H32,'재무상태표'!$H$7:$H$57) -> 176000000 | G32: =E32-F32 -> 52536000 | H32: 매입채무
A33: BS | B33: 미지급금 | D33: =SUMIF('재무상태표'!$C$7:$C$57,$H33,'재무상태표'!$D$7:$D$57) -> 149096000 | E33: =SUMIF('재무상태표'!$C$7:$C$57,$H33,'재무상태표'!$G$7:$G$57) -> 149096000 | F33: =SUMIF('재무상태표'!$C$7:$C$57,$H33,'재무상태표'!$H$7:$H$57) -> 119600000 | G33: =E33-F33 -> 29496000 | H33: 미지급금
A34: BS | B34: 예수금 | D34: =SUMIF('재무상태표'!$C$7:$C$57,$H34,'재무상태표'!$D$7:$D$57) -> 188039650 | E34: =SUMIF('재무상태표'!$C$7:$C$57,$H34,'재무상태표'!$G$7:$G$57) -> 188039650 | F34: =SUMIF('재무상태표'!$C$7:$C$57,$H34,'재무상태표'!$H$7:$H$57) -> 151620000 | G34: =E34-F34 -> 36419650 | H34: 예수금
A35: BS | B35: 부가세예수금 | D35: =SUMIF('재무상태표'!$C$7:$C$57,$H35,'재무상태표'!$D$7:$D$57) -> 389788078 | E35: =SUMIF('재무상태표'!$C$7:$C$57,$H35,'재무상태표'!$G$7:$G$57) -> 389788078 | F35: =SUMIF('재무상태표'!$C$7:$C$57,$H35,'재무상태표'!$H$7:$H$57) -> 414939340 | G35: =E35-F35 -> -25151262 | H35: 부가세예수금
A36: BS | B36: 선수금 | C36: 13 | D36: =SUMIF('재무상태표'!$C$7:$C$57,$H36,'재무상태표'!$D$7:$D$57) -> 554533357 | E36: =SUMIF('재무상태표'!$C$7:$C$57,$H36,'재무상태표'!$G$7:$G$57) -> 554533357 | F36: =SUMIF('재무상태표'!$C$7:$C$57,$H36,'재무상태표'!$H$7:$H$57) -> 477191701 | G36: =E36-F36 -> 77341656 | H36: 선수금
A37: BS | B37: 미지급비용 | D37: =SUMIF('재무상태표'!$C$7:$C$57,$H37,'재무상태표'!$D$7:$D$57) -> 0 | E37: =SUMIF('재무상태표'!$C$7:$C$57,$H37,'재무상태표'!$G$7:$G$57) -> 38400000 | F37: =SUMIF('재무상태표'!$C$7:$C$57,$H37,'재무상태표'!$H$7:$H$57) -> 0 | G37: =E37-F37 -> 38400000 | H37: 미지급비용
A38: BS | B38: 단기차입금 | C38: 10,17 | D38: =SUMIF('재무상태표'!$C$7:$C$57,$H38,'재무상태표'!$D$7:$D$57) -> 2000000000 | E38: =SUMIF('재무상태표'!$C$7:$C$57,$H38,'재무상태표'!$G$7:$G$57) -> 2000000000 | F38: =SUMIF('재무상태표'!$C$7:$C$57,$H38,'재무상태표'!$H$7:$H$57) -> 2000000000 | G38: =E38-F38 -> 0 | H38: 단기차입금
A39: BS | B39: Ⅱ. 비유동부채 | D39: =SUM(D40) -> 3000000000 | E39: =SUM(E40) -> 3000000000 | F39: =SUM(F40) -> 3000000000 | G39: =E39-F39 -> 0 | H39: 비유동부채
A40: BS | B40: 장기차입금 | C40: 10 | D40: =SUMIF('재무상태표'!$C$7:$C$57,$H40,'재무상태표'!$D$7:$D$57) -> 3000000000 | E40: =SUMIF('재무상태표'!$C$7:$C$57,$H40,'재무상태표'!$G$7:$G$57) -> 3000000000 | F40: =SUMIF('재무상태표'!$C$7:$C$57,$H40,'재무상태표'!$H$7:$H$57) -> 3000000000 | G40: =E40-F40 -> 0 | H40: 장기차입금
A41: BS | B41: 부채총계 | D41: =D31+D39 -> 6509993085 | E41: =E31+E39 -> 6548393085 | F41: =F31+F39 -> 6339351041 | G41: =E41-F41 -> 209042044 | H41: 부채총계
...

Sheet 공시용PL
B1: 손익계산서(공시용)
B2: 제7(당)기 2024-01-01 ~ 2024-12-31 · 제6(전)기 2023-01-01 ~ 2023-12-31 · 단위: 원 · 정산표를 공시용 계정과목(H 열)으로 SUMIF
A4: 구분 | B4: 과목 | C4: 주석 | D4: 당기(회사제시) | E4: 당기(최종) | F4: 전기(최종) | G4: 증감 | H4: 표시과목(정산표 연결)
A5: IS | B5: Ⅰ. 매출액 | C5: 13,18 | D5: =SUM(D6,D7) -> 9990547268 | E5: =SUM(E6,E7) -> 9990547268 | F5: =SUM(F6,F7) -> 8526408762 | G5: =E5-F5 -> 1464138506 | H5: 매출액
A6: IS | B6: 국내구독매출 | D6: =SUMIF('손익계산서'!$C$7:$C$43,$H6,'손익계산서'!$E$7:$E$43) -> 8175103384 | E6: =SUMIF('손익계산서'!$C$7:$C$43,$H6,'손익계산서'!$H$7:$H$43) -> 8175103384 | F6: =SUMIF('손익계산서'!$C$7:$C$43,$H6,'손익계산서'!$I$7:$I$43) -> 7008516131 | G6: =E6-F6 -> 1166587253 | H6: 국내구독매출
A7: IS | B7: 해외구독매출 | D7: =SUMIF('손익계산서'!$C$7:$C$43,$H7,'손익계산서'!$E$7:$E$43) -> 1815443884 | E7: =SUMIF('손익계산서'!$C$7:$C$43,$H7,'손익계산서'!$H$7:$H$43) -> 1815443884 | F7: =SUMIF('손익계산서'!$C$7:$C$43,$H7,'손익계산서'!$I$7:$I$43) -> 1517892631 | G7: =E7-F7 -> 297551253 | H7: 해외구독매출
A8: IS | B8: Ⅱ. 매출원가 | D8: =SUM(D9) -> 2363760000 | E8: =SUM(E9) -> 2402160000 | F8: =SUM(F9) -> 1973374440 | G8: =E8-F8 -> 428785560 | H8: 매출원가
A9: IS | B9: 용역매출원가 | D9: =SUMIF('손익계산서'!$C$7:$C$43,$H9,'손익계산서'!$E$7:$E$43) -> 2363760000 | E9: =SUMIF('손익계산서'!$C$7:$C$43,$H9,'손익계산서'!$H$7:$H$43) -> 2402160000 | F9: =SUMIF('손익계산서'!$C$7:$C$43,$H9,'손익계산서'!$I$7:$I$43) -> 1973374440 | G9: =E9-F9 -> 428785560 | H9: 용역매출원가
A10: IS | B10: Ⅲ. 매출총이익 | D10: =D5-D8 -> 7626787268 | E10: =E5-E8 -> 7588387268 | F10: =F5-F8 -> 6553034322 | G10: =E10-F10 -> 1035352946 | H10: 매출총이익
A11: IS | B11: Ⅳ. 판매비와관리비 | D11: =SUM(D12,D13,D14,D15,D16,D17,D18,D19,D20,D21,D22,D23,D24,D25,D26,D27,D28,D29,D30) -> 11939296577 | E11: =SUM(E12,E13,E14,E15,E16,E17,E18,E19,E20,E21,E22,E23,E24,E25,E26,E27,E28,E29,E30) -> 11894296577 | F11: =SUM(F12,F13,F14,F15,F16,F17,F18,F19,F20,F21,F22,F23,F24,F25,F26,F27,F28,F29,F30) -> 10115191863 | G11: =E11-F11 -> 1779104714 | H11: 판매비와관리비
A12: IS | B12: 급여 | D12: =SUMIF('손익계산서'!$C$7:$C$43,$H12,'손익계산서'!$E$7:$E$43) -> 3609528000 | E12: =SUMIF('손익계산서'!$C$7:$C$43,$H12,'손익계산서'!$H$7:$H$43) -> 3609528000 | F12: =SUMIF('손익계산서'!$C$7:$C$43,$H12,'손익계산서'!$I$7:$I$43) -> 3108525513 | G12: =E12-F12 -> 501002487 | H12: 급여
A13: IS | B13: 상여금 | D13: =SUMIF('손익계산서'!$C$7:$C$43,$H13,'손익계산서'!$E$7:$E$43) -> 240000000 | E13: =SUMIF('손익계산서'!$C$7:$C$43,$H13,'손익계산서'!$H$7:$H$43) -> 240000000 | F13: =SUMIF('손익계산서'!$C$7:$C$43,$H13,'손익계산서'!$I$7:$I$43) -> 186000000 | G13: =E13-F13 -> 54000000 | H13: 상여금
A14: IS | B14: 퇴직급여 | C14: 14 | D14: =SUMIF('손익계산서'!$C$7:$C$43,$H14,'손익계산서'!$E$7:$E$43) -> 300793996 | E14: =SUMIF('손익계산서'!$C$7:$C$43,$H14,'손익계산서'!$H$7:$H$43) -> 300793996 | F14: =SUMIF('손익계산서'!$C$7:$C$43,$H14,'손익계산서'!$I$7:$I$43) -> 259043789 | G14: =E14-F14 -> 41750207 | H14: 퇴직급여
A15: IS | B15: 복리후생비 | D15: =SUMIF('손익계산서'!$C$7:$C$43,$H15,'손익계산서'!$E$7:$E$43) -> 597765320 | E15: =SUMIF('손익계산서'!$C$7:$C$43,$H15,'손익계산서'!$H$7:$H$43) -> 597765320 | F15: =SUMIF('손익계산서'!$C$7:$C$43,$H15,'손익계산서'!$I$7:$I$43) -> 504334600 | G15: =E15-F15 -> 93430720 | H15: 복리후생비
A16: IS | B16: 여비교통비 | D16: =SUMIF('손익계산서'!$C$7:$C$43,$H16,'손익계산서'!$E$7:$E$43) -> 120960000 | E16: =SUMIF('손익계산서'!$C$7:$C$43,$H16,'손익계산서'!$H$7:$H$43) -> 120960000 | F16: =SUMIF('손익계산서'!$C$7:$C$43,$H16,'손익계산서'!$I$7:$I$43) -> 99078336 | G16: =E16-F16 -> 21881664 | H16: 여비교통비
A17: IS | B17: 기업업무추진비 | D17: =SUMIF('손익계산서'!$C$7:$C$43,$H17,'손익계산서'!$E$7:$E$43) -> 60480000 | E17: =SUMIF('손익계산서'!$C$7:$C$43,$H17,'손익계산서'!$H$7:$H$43) -> 60480000 | F17: =SUMIF('손익계산서'!$C$7:$C$43,$H17,'손익계산서'!$I$7:$I$43) -> 50004864 | G17: =E17-F17 -> 10475136 | H17: 기업업무추진비
A18: IS | B18: 통신비 | D18: =SUMIF('손익계산서'!$C$7:$C$43,$H18,'손익계산서'!$E$7:$E$43) -> 60480000 | E18: =SUMIF('손익계산서'!$C$7:$C$43,$H18,'손익계산서'!$H$7:$H$43) -> 60480000 | F18: =SUMIF('손익계산서'!$C$7:$C$43,$H18,'손익계산서'!$I$7:$I$43) -> 54643680 | G18: =E18-F18 -> 5836320 | H18: 통신비
A19: IS | B19: 세금과공과 | D19: =SUMIF('손익계산서'!$C$7:$C$43,$H19,'손익계산서'!$E$7:$E$43) -> 330632820 | E19: =SUMIF('손익계산서'!$C$7:$C$43,$H19,'손익계산서'!$H$7:$H$43) -> 330632820 | F19: =SUMIF('손익계산서'!$C$7:$C$43,$H19,'손익계산서'!$I$7:$I$43) -> 282988630 | G19: =E19-F19 -> 47644190 | H19: 세금과공과
A20: IS | B20: 감가상각비 | C20: 8 | D20: =SUMIF('손익계산서'!$C$7:$C$43,$H20,'손익계산서'!$E$7:$E$43) -> 437310318 | E20: =SUMIF('손익계산서'!$C$7:$C$43,$H20,'손익계산서'!$H$7:$H$43) -> 437310318 | F20: =SUMIF('손익계산서'!$C$7:$C$43,$H20,'손익계산서'!$I$7:$I$43) -> 385458225 | G20: =E20-F20 -> 51852093 | H20: 감가상각비
A21: IS | B21: 지급임차료 | C21: 17 | D21: =SUMIF('손익계산서'!$C$7:$C$43,$H21,'손익계산서'!$E$7:$E$43) -> 410160000 | E21: =SUMIF('손익계산서'!$C$7:$C$43,$H21,'손익계산서'!$H$7:$H$43) -> 410160000 | F21: =SUMIF('손익계산서'!$C$7:$C$43,$H21,'손익계산서'!$I$7:$I$43) -> 386160000 | G21: =E21-F21 -> 24000000 | H21: 지급임차료
A22: IS | B22: 보험료 | D22: =SUMIF('손익계산서'!$C$7:$C$43,$H22,'손익계산서'!$E$7:$E$43) -> 152379460 | E22: =SUMIF('손익계산서'!$C$7:$C$43,$H22,'손익계산서'!$H$7:$H$43) -> 152379460 | F22: =SUMIF('손익계산서'!$C$7:$C$43,$H22,'손익계산서'!$I$7:$I$43) -> 134794870 | G22: =E22-F22 -> 17584590 | H22: 보험료
A23: IS | B23: 차량유지비 | D23: =SUMIF('손익계산서'!$C$7:$C$43,$H23,'손익계산서'!$E$7:$E$43) -> 50400000 | E23: =SUMIF('손익계산서'!$C$7:$C$43,$H23,'손익계산서'!$H$7:$H$43) -> 50400000 | F23: =SUMIF('손익계산서'!$C$7:$C$43,$H23,'손익계산서'!$I$7:$I$43) -> 46000080 | G23: =E23-F23 -> 4399920 | H23: 차량유지비
A24: IS | B24: 도서인쇄비 | D24: =SUMIF('손익계산서'!$C$7:$C$43,$H24,'손익계산서'!$E$7:$E$43) -> 20160000 | E24: =SUMIF('손익계산서'!$C$7:$C$43,$H24,'손익계산서'!$H$7:$H$43) -> 20160000 | F24: =SUMIF('손익계산서'!$C$7:$C$43,$H24,'손익계산서'!$I$7:$I$43) -> 17559360 | G24: =E24-F24 -> 2600640 | H24: 도서인쇄비
A25: IS | B25: 소모품비 | D25: =SUMIF('손익계산서'!$C$7:$C$43,$H25,'손익계산서'!$E$7:$E$43) -> 80640000 | E25: =SUMIF('손익계산서'!$C$7:$C$43,$H25,'손익계산서'!$H$7:$H$43) -> 80640000 | F25: =SUMIF('손익계산서'!$C$7:$C$43,$H25,'손익계산서'!$I$7:$I$43) -> 68156928 | G25: =E25-F25 -> 12483072 | H25: 소모품비
A26: IS | B26: 지급수수료 | C26: 18 | D26: =SUMIF('손익계산서'!$C$7:$C$43,$H26,'손익계산서'!$E$7:$E$43) -> 506849667 | E26: =SUMIF('손익계산서'!$C$7:$C$43,$H26,'손익계산서'!$H$7:$H$43) -> 461849667 | F26: =SUMIF('손익계산서'!$C$7:$C$43,$H26,'손익계산서'!$I$7:$I$43) -> 377515917 | G26: =E26-F26 -> 84333750 | H26: 지급수수료
A27: IS | B27: 광고선전비 | D27: =SUMIF('손익계산서'!$C$7:$C$43,$H27,'손익계산서'!$E$7:$E$43) -> 692400000 | E27: =SUMIF('손익계산서'!$C$7:$C$43,$H27,'손익계산서'!$H$7:$H$43) -> 692400000 | F27: =SUMIF('손익계산서'!$C$7:$C$43,$H27,'손익계산서'!$I$7:$I$43) -> 532594080 | G27: =E27-F27 -> 159805920 | H27: 광고선전비
A28: IS | B28: 무형자산상각비 | C28: 9 | D28: =SUMIF('손익계산서'!$C$7:$C$43,$H28,'손익계산서'!$E$7:$E$43) -> 38999996 | E28: =SUMIF('손익계산서'!$C$7:$C$43,$H28,'손익계산서'!$H$7:$H$43) -> 38999996 | F28: =SUMIF('손익계산서'!$C$7:$C$43,$H28,'손익계산서'!$I$7:$I$43) -> 32016663 | G28: =E28-F28 -> 6983333 | H28: 무형자산상각비
A29: IS | B29: 경상연구개발비 | D29: =SUMIF('손익계산서'!$C$7:$C$43,$H29,'손익계산서'!$E$7:$E$43) -> 4049357000 | E29: =SUMIF('손익계산서'!$C$7:$C$43,$H29,'손익계산서'!$H$7:$H$43) -> 4049357000 | F29: =SUMIF('손익계산서'!$C$7:$C$43,$H29,'손익계산서'!$I$7:$I$43) -> 3455316328 | G29: =E29-F29 -> 594040672 | H29: 경상연구개발비
A30: IS | B30: 주식보상비용 | C30: 12 | D30: =SUMIF('손익계산서'!$C$7:$C$43,$H30,'손익계산서'!$E$7:$E$43) -> 180000000 | E30: =SUMIF('손익계산서'!$C$7:$C$43,$H30,'손익계산서'!$H$7:$H$43) -> 180000000 | F30: =SUMIF('손익계산서'!$C$7:$C$43,$H30,'손익계산서'!$I$7:$I$43) -> 135000000 | G30: =E30-F30 -> 45000000 | H30: 주식보상비용
A31: IS | B31: Ⅴ. 영업이익(손실) | D31: =D10-D11 -> -4312509309 | E31: =E10-E11 -> -4305909309 | F31: =F10-F11 -> -3562157541 | G31: =E31-F31 -> -743751768 | H31: 영업이익
A32: IS | B32: Ⅵ. 영업외수익 | D32: =SUM(D33,D34,D35) -> 125560260 | E32: =SUM(E33,E34,E35) -> 129089027 | F32: =SUM(F33,F34,F35) -> 115797660 | G32: =E32-F32 -> 13291367 | H32: 영업외수익
A33: IS | B33: 이자수익 | D33: =SUMIF('손익계산서'!$C$7:$C$43,$H33,'손익계산서'!$E$7:$E$43) -> 111870137 | E33: =SUMIF('손익계산서'!$C$7:$C$43,$H33,'손익계산서'!$H$7:$H$43) -> 115398904 | F33: =SUMIF('손익계산서'!$C$7:$C$43,$H33,'손익계산서'!$I$7:$I$43) -> 111187252 | G33: =E33-F33 -> 4211652 | H33: 이자수익
A34: IS | B34: 외환차익 | D34: =SUMIF('손익계산서'!$C$7:$C$43,$H34,'손익계산서'!$E$7:$E$43) -> 921967 | E34: =SUMIF('손익계산서'!$C$7:$C$43,$H34,'손익계산서'!$H$7:$H$43) -> 921967 | F34: =SUMIF('손익계산서'!$C$7:$C$43,$H34,'손익계산서'!$I$7:$I$43) -> 1483920 | G34: =E34-F34 -> -561953 | H34: 외환차익
A35: IS | B35: 외화환산이익 | C35: 15 | D35: =SUMIF('손익계산서'!$C$7:$C$43,$H35,'손익계산서'!$E$7:$E$43) -> 12768156 | E35: =SUMIF('손익계산서'!$C$7:$C$43,$H35,'손익계산서'!$H$7:$H$43) -> 12768156 | F35: =SUMIF('손익계산서'!$C$7:$C$43,$H35,'손익계산서'!$I$7:$I$43) -> 3126488 | G35: =E35-F35 -> 9641668 | H35: 외화환산이익
A36: IS | B36: Ⅶ. 영업외비용 | D36: =SUM(D37,D38) -> 241974589 | E36: =SUM(E37,E38) -> 241974589 | F36: =SUM(F37,F38) -> 173861370 | G36: =E36-F36 -> 68113219 | H36: 영업외비용
A37: IS | B37: 이자비용 | C37: 10 | D37: =SUMIF('손익계산서'!$C$7:$C$43,$H37,'손익계산서'!$E$7:$E$43) -> 240000000 | E37: =SUMIF('손익계산서'!$C$7:$C$43,$H37,'손익계산서'!$H$7:$H$43) -> 240000000 | F37: =SUMIF('손익계산서'!$C$7:$C$43,$H37,'손익계산서'!$I$7:$I$43) -> 171000000 | G37: =E37-F37 -> 69000000 | H37: 이자비용
A38: IS | B38: 외환차손 | D38: =SUMIF('손익계산서'!$C$7:$C$43,$H38,'손익계산서'!$E$7:$E$43) -> 1974589 | E38: =SUMIF('손익계산서'!$C$7:$C$43,$H38,'손익계산서'!$H$7:$H$43) -> 1974589 | F38: =SUMIF('손익계산서'!$C$7:$C$43,$H38,'손익계산서'!$I$7:$I$43) -> 2861370 | G38: =E38-F38 -> -886781 | H38: 외환차손
A39: IS | B39: Ⅷ. 법인세비용차감전순이익(손실) | D39: =D31+D32-D36 -> -4428923638 | E39: =E31+E32-E36 -> -4418794871 | F39: =F31+F32-F36 -> -3620221251 | G39: =E39-F39 -> -798573620 | H39: 법인세비용차감전순이익
A40: IS | B40: Ⅸ. 법인세비용 | C40: 16 | D40: =SUM(0) -> 0 | E40: =SUM(0) -> 0 | F40: =SUM(0) -> 0 | G40: =E40-F40 -> 0 | H40: 법인세비용
A41: IS | B41: Ⅹ. 당기순이익(손실) | D41: =D39-D40 -> -4428923638 | E41: =E39-E40 -> -4418794871 | F41: =F39-F40 -> -3620221251 | G41: =E41-F41 -> -798573620 | H41: 당기순이익
...

Sheet 공시용자본변동표
A1: 자본변동표(공시용)
A2: 제7(당)기 2024-01-01 ~ 2024-12-31 · 제6(전)기 2023-01-01 ~ 2023-12-31 · 단위: 원
A4: 구분 | B4: 자본금 | C4: 자본잉여금 | D4: 자본조정 | E4: 기타포괄손익누계액 | F4: 이익잉여금(결손금) | G4: 총계 | H4: 근거
A5: 2023.01.01(전기초) | B5: 350000000 | C5: 26800000000 | D5: 105000000 | E5: 0 | F5: -19694151945 | G5: =SUM(B5:F5) -> 7560848055 | H5: 전기 감사보고서 자본변동표
A6: 주식보상비용 | D6: 135000000 | G6: =SUM(B6:F6) -> 135000000 | H6: 2차 주식매수선택권(2023-03-29 부여)
A7: 당기순손실 | F7: ='손익계산서'!I43 -> -3620221251 | G7: =SUM(B7:F7) -> -3620221251 | H7: 정산표(손익계산서) 전기 Final
A8: 2023.12.31(전기말) | B8: =SUM(B5:B7) -> 350000000 | C8: =SUM(C5:C7) -> 26800000000 | D8: =SUM(D5:D7) -> 240000000 | E8: =SUM(E5:E7) -> 0 | F8: =SUM(F5:F7) -> -23314373196 | G8: =SUM(B8:F8) -> 4075626804
A10: 2024.01.01(당기초) | B10: =B8 -> 350000000 | C10: =C8 -> 26800000000 | D10: =D8 -> 240000000 | E10: =E8 -> 0 | F10: =F8 -> -23314373196 | G10: =SUM(B10:F10) -> 4075626804
A11: 유상증자(상환전환우선주 30,000주) | B11: =-('TB'!H31-'TB'!I31) -> 15000000 | C11: =-('TB'!H32-'TB'!I32) -> 2985000000 | G11: =SUM(B11:F11) -> 3000000000 | H11: 2024-07-15 납입, 1주 100,000원
A12: 주식보상비용 | D12: ='TB'!H56 -> 180000000 | G12: =SUM(B12:F12) -> 180000000 | H12: TB 주식보상비용 최종
A13: 당기순손실 | F13: ='손익계산서'!H43 -> -4418794871 | G13: =SUM(B13:F13) -> -4418794871 | H13: 정산표(손익계산서) Final
A14: 2024.12.31(당기말) | B14: =SUM(B10:B13) -> 365000000 | C14: =SUM(C10:C13) -> 29785000000 | D14: =SUM(D10:D13) -> 420000000 | E14: =SUM(E10:E13) -> 0 | F14: =SUM(F10:F13) -> -27733168067 | G14: =SUM(B14:F14) -> 2836831933
A16: 공시용BS 당기말(최종) | B16: ='공시용BS'!E43 -> 365000000 | C16: ='공시용BS'!E46 -> 29785000000 | D16: ='공시용BS'!E48 -> 420000000 | E16: 0 | F16: ='공시용BS'!E50 -> -27733168067 | G16: ='공시용BS'!E52 -> 2836831933
A17: 대사(당기말 − 공시용BS) | B17: =B14-B16 -> 0 | C17: =C14-C16 -> 0 | D17: =D14-D16 -> 0 | E17: =E14-E16 -> 0 | F17: =F14-F16 -> 0 | G17: =G14-G16 -> 0 | H17: =IF(SUMPRODUCT(ABS(B17:G17))<1,"OK","변동 줄 확인") -> OK
A18: 공시용BS 전기말(최종) | B18: ='공시용BS'!F43 -> 350000000 | C18: ='공시용BS'!F46 -> 26800000000 | D18: ='공시용BS'!F48 -> 240000000 | E18: 0 | F18: ='공시용BS'!F50 -> -23314373196 | G18: ='공시용BS'!F52 -> 4075626804
A19: 대사(전기말 − 공시용BS) | B19: =B8-B18 -> 0 | C19: =C8-C18 -> 0 | D19: =D8-D18 -> 0 | E19: =E8-E18 -> 0 | F19: =F8-F18 -> 0 | G19: =G8-G18 -> 0 | H19: =IF(SUMPRODUCT(ABS(B19:G19))<1,"OK","변동 줄 확인") -> OK

Sheet CF정산표
A1: 현금흐름 정산표 · 제7기
A2: 1) 현금을 뺀 재무상태표 계정의 증감을 현금흐름 효과(유입 +)로 바꾸고, 2) 그 효과를 현금흐름표 과목으로 배분한다. 배분 합계가 효과와 같아야 한다(판정 OK). 정기예금 3,000,000,000 은 2024-01-16 같은 금액으로 재예치해 현금 흐름이 없다.
A4: 계정코드 | B4: 계정과목 | C4: 전기말(차변 +) | D4: 당기말(차변 +) | E4: 증감 | F4: 현금흐름 효과 | G4: 배분 합계 | H4: 차이 | I4: 판정
A5: 10500 | B5: 정기예적금 | C5: ='TB'!I6 -> 3000000000 | D5: ='TB'!H6 -> 3000000000 | E5: =D5-C5 -> 0 | F5: =-E5 -> 0 | G5: =SUMIF('CF정산표'!$A$42:$A$65,$A5,'CF정산표'!$E$42:$E$65) -> 0 | H5: =F5-G5 -> 0 | I5: =IF(ROUND(H5,0)=0,"OK","배분 확인") -> OK
A6: 10800 | B6: 외상매출금 | C6: ='TB'!I7 -> 540152971 | D6: ='TB'!H7 -> 681160188 | E6: =D6-C6 -> 141007217 | F6: =-E6 -> -141007217 | G6: =SUMIF('CF정산표'!$A$42:$A$65,$A6,'CF정산표'!$E$42:$E$65) -> -141007217 | H6: =F6-G6 -> 0 | I6: =IF(ROUND(H6,0)=0,"OK","배분 확인") -> OK
A7: 11600 | B7: 미수수익 | C7: ='TB'!I8 -> 109002740 | D7: ='TB'!H8 -> 103561644 | E7: =D7-C7 -> -5441096 | F7: =-E7 -> 5441096 | G7: =SUMIF('CF정산표'!$A$42:$A$65,$A7,'CF정산표'!$E$42:$E$65) -> 5441096 | H7: =F7-G7 -> 0 | I7: =IF(ROUND(H7,0)=0,"OK","배분 확인") -> OK
A8: 13300 | B8: 선급비용 | C8: ='TB'!I9 -> 0 | D8: ='TB'!H9 -> 45000000 | E8: =D8-C8 -> 45000000 | F8: =-E8 -> -45000000 | G8: =SUMIF('CF정산표'!$A$42:$A$65,$A8,'CF정산표'!$E$42:$E$65) -> -45000000 | H8: =F8-G8 -> 0 | I8: =IF(ROUND(H8,0)=0,"OK","배분 확인") -> OK
A9: 13500 | B9: 부가세대급금 | C9: ='TB'!I10 -> 151000000 | D9: ='TB'!H10 -> 111738000 | E9: =D9-C9 -> -39262000 | F9: =-E9 -> 39262000 | G9: =SUMIF('CF정산표'!$A$42:$A$65,$A9,'CF정산표'!$E$42:$E$65) -> 39262000 | H9: =F9-G9 -> 0 | I9: =IF(ROUND(H9,0)=0,"OK","배분 확인") -> OK
A10: 13600 | B10: 선납세금 | C10: ='TB'!I11 -> 0 | D10: ='TB'!H11 -> 18609360 | E10: =D10-C10 -> 18609360 | F10: =-E10 -> -18609360 | G10: =SUMIF('CF정산표'!$A$42:$A$65,$A10,'CF정산표'!$E$42:$E$65) -> -18609360 | H10: =F10-G10 -> 0 | I10: =IF(ROUND(H10,0)=0,"OK","배분 확인") -> OK
A11: 17800 | B11: 투자유가증권 | C11: ='TB'!I12 -> 0 | D11: ='TB'!H12 -> 0 | E11: =D11-C11 -> 0 | F11: =-E11 -> 0 | G11: =SUMIF('CF정산표'!$A$42:$A$65,$A11,'CF정산표'!$E$42:$E$65) -> 0 | H11: =F11-G11 -> 0 | I11: =IF(ROUND(H11,0)=0,"OK","배분 확인") -> OK
A12: 18000 | B12: 지분법적용투자주식 | C12: ='TB'!I13 -> 1180000000 | D12: ='TB'!H13 -> 1180000000 | E12: =D12-C12 -> 0 | F12: =-E12 -> 0 | G12: =SUMIF('CF정산표'!$A$42:$A$65,$A12,'CF정산표'!$E$42:$E$65) -> 0 | H12: =F12-G12 -> 0 | I12: =IF(ROUND(H12,0)=0,"OK","배분 확인") -> OK
A13: 17900 | B13: 장기대여금 | C13: ='TB'!I14 -> 60000000 | D13: ='TB'!H14 -> 60000000 | E13: =D13-C13 -> 0 | F13: =-E13 -> 0 | G13: =SUMIF('CF정산표'!$A$42:$A$65,$A13,'CF정산표'!$E$42:$E$65) -> 0 | H13: =F13-G13 -> 0 | I13: =IF(ROUND(H13,0)=0,"OK","배분 확인") -> OK
A14: 21200 | B14: 비품 | C14: ='TB'!I15 -> 1130900000 | D14: ='TB'!H15 -> 1245000000 | E14: =D14-C14 -> 114100000 | F14: =-E14 -> -114100000 | G14: =SUMIF('CF정산표'!$A$42:$A$65,$A14,'CF정산표'!$E$42:$E$65) -> -114100000 | H14: =F14-G14 -> 0 | I14: =IF(ROUND(H14,0)=0,"OK","배분 확인") -> OK
A15: 21300 | B15: 감가상각누계액 | C15: ='TB'!I16 -> -493333152 | D15: ='TB'!H16 -> -771043482 | E15: =D15-C15 -> -277710330 | F15: =-E15 -> 277710330 | G15: =SUMIF('CF정산표'!$A$42:$A$65,$A15,'CF정산표'!$E$42:$E$65) -> 277710330 | H15: =F15-G15 -> 0 | I15: =IF(ROUND(H15,0)=0,"OK","배분 확인") -> OK
A16: 22100 | B16: 시설장치 | C16: ='TB'!I17 -> 798000000 | D16: ='TB'!H17 -> 798000000 | E16: =D16-C16 -> 0 | F16: =-E16 -> 0 | G16: =SUMIF('CF정산표'!$A$42:$A$65,$A16,'CF정산표'!$E$42:$E$65) -> 0 | H16: =F16-G16 -> 0 | I16: =IF(ROUND(H16,0)=0,"OK","배분 확인") -> OK
... A32: 38900 | B32: 주식매수선택권 | C32: ='TB'!I33 -> -240000000 | D32: ='TB'!H33 -> -420000000 | E32: =D32-C32 -> -180000000 | F32: =-E32 -> 180000000 | G32: =SUMIF('CF정산표'!$A$42:$A$65,$A32,'CF정산표'!$E$42:$E$65) -> 180000000 | H32: =F32-G32 -> 0 | I32: =IF(ROUND(H32,0)=0,"OK","배분 확인") -> OK
A33: 37700 | B33: 미처리결손금 | C33: 23314373196 | D33: ='TB'!H34 -> 23314373196 | E33: =D33-C33 -> 0 | F33: =-E33 -> 0 | G33: =SUMIF('CF정산표'!$A$42:$A$65,$A33,'CF정산표'!$E$42:$E$65) -> 0 | H33: =F33-G33 -> 0 | I33: =IF(ROUND(H33,0)=0,"OK","배분 확인") -> OK
A34: NI | B34: 당기순손익(손익 계정 합계) | F34: ='손익계산서'!H43 -> -4418794871 | G34: =SUMIF('CF정산표'!$A$42:$A$65,$A34,'CF정산표'!$E$42:$E$65) -> -4418794871 | H34: =F34-G34 -> 0 | I34: =IF(ROUND(H34,0)=0,"OK","배분 확인") -> OK
A35: FX | B35: 외화예금 기말 환산(현금 계정) | F35: 0 | G35: =SUMIF('CF정산표'!$A$42:$A$65,$A35,'CF정산표'!$E$42:$E$65) -> 0 | H35: =F35-G35 -> 0 | I35: =IF(ROUND(H35,0)=0,"OK","배분 확인") -> OK
B36: 합계(= 현금 증감) | F36: =SUM(F5:F35) -> -875455994 | I36: =IF(COUNTIF(I5:I35,"OK")=31,"OK","배분 확인") -> OK
B37: 현금및현금성자산 증감(TB) | F37: ='TB'!H5-'TB'!I5 -> -875455994
B38: 판정 | F38: =IF(ROUND(F36-F37,0)=0,"OK","차이") -> OK
A40: 배분
A41: 계정코드 | B41: 계정과목 | C41: 현금흐름표 과목 | D41: 활동 | E41: 금액 | F41: 근거
A42: NI | B42: 당기순손익(손익 계정 합계) | C42: 당기순손실 | D42: 영업 | E42: ='손익계산서'!H43 -> -4418794871 | F42: 정산표(손익계산서) Final
A43: 21300 | B43: 감가상각누계액(비품) | C43: 감가상각비 | D43: 영업 · 조정 | E43: 277710330 | F43: 자산대장 비품 상각
A44: 22200 | B44: 감가상각누계액(시설장치) | C44: 감가상각비 | D44: 영업 · 조정 | E44: 159599988 | F44: 자산대장 시설장치 상각
A45: 24000 | B45: 소프트웨어 | C45: 무형자산상각비 | D45: 영업 · 조정 | E45: 33200000 | F45: 자산대장 소프트웨어 상각
A46: 23200 | B46: 산업재산권 | C46: 무형자산상각비 | D46: 영업 · 조정 | E46: 5799996 | F46: 자산대장 산업재산권 상각
A47: 38900 | B47: 주식매수선택권 | C47: 주식보상비용 | D47: 영업 · 조정 | E47: 180000000 | F47: TB 주식보상비용
A48: 10800 | B48: 매출채권 | C48: 외화환산이익 | D48: 영업 · 조정 | E48: -879893 | F48: 일본 지점 매출채권 기말 환산
A49: FX | B49: 외화예금 기말 환산(현금 계정) | C49: 외화환산이익 | D49: 영업 · 조정 | E49: -11888263 | F49: USD · JPY 예금 기말 환산
A50: FX | B50: 외화예금 기말 환산(현금 계정) | C50: 외화표시 현금의 환율변동효과 | D50: 환율 | E50: 11888263 | F50: 현금흐름표 별도 줄
A51: 10800 | B51: 외상매출금 | C51: 매출채권의 증가 | D51: 영업 · 운전자본 | E51: -140127324 | F51: 계정 증감(외화 환산분 제외)
A52: 11600 | B52: 미수수익 | C52: 미수수익의 감소(증가) | D52: 영업 · 운전자본 | E52: 5441096 | F52: 계정 증감
A53: 13300 | B53: 선급비용 | C53: 선급비용의 증가 | D53: 영업 · 운전자본 | E53: -45000000 | F53: 계정 증감
A54: 13500 | B54: 부가세대급금 | C54: 부가세대급금의 감소(증가) | D54: 영업 · 운전자본 | E54: 39262000 | F54: 계정 증감
A55: 13600 | B55: 선납세금 | C55: 당기법인세자산의 증가 | D55: 영업 · 운전자본 | E55: -18609360 | F55: 계정 증감
A56: 25100 | B56: 외상매입금 | C56: 매입채무의 증가 | D56: 영업 · 운전자본 | E56: 52536000 | F56: 계정 증감
A57: 25300 | B57: 미지급금 | C57: 미지급금의 증가 | D57: 영업 · 운전자본 | E57: 29496000 | F57: 계정 증감
...

Sheet 공시용CF
B1: 현금흐름표(공시용, 간접법)
B2: 제7(당)기 2024-01-01 ~ 2024-12-31 · 제6(전)기 2023-01-01 ~ 2023-12-31 · 단위: 원 · 당기는 CF정산표 배분을 SUMIF, 전기는 전기 감사보고서
A4: 구분 | B4: 과목 | C4: 당기 | D4: 전기 | E4: 현금흐름표 과목(연결)
A5: CF | B5: Ⅰ. 영업활동으로 인한 현금흐름 | C5: =SUM(C6,C7,C11,C13) -> -3725244257 | D5: =SUM(D6,D7,D11,D13) -> -3056051158
A6: CF | B6: 1. 당기순손실 | C6: =SUMIF('CF정산표'!$C$42:$C$65,$E6,'CF정산표'!$E$42:$E$65) -> -4418794871 | D6: -3620221251 | E6: 당기순손실
A7: CF | B7: 2. 현금의 유출이 없는 비용 등의 가산 | C7: =SUM(C8,C9,C10) -> 656310314 | D7: =SUM(D8,D9,D10) -> 552474888
A8: CF | B8: 감가상각비 | C8: =SUMIF('CF정산표'!$C$42:$C$65,$E8,'CF정산표'!$E$42:$E$65) -> 437310318 | D8: 385458225 | E8: 감가상각비
A9: CF | B9: 무형자산상각비 | C9: =SUMIF('CF정산표'!$C$42:$C$65,$E9,'CF정산표'!$E$42:$E$65) -> 38999996 | D9: 32016663 | E9: 무형자산상각비
A10: CF | B10: 주식보상비용 | C10: =SUMIF('CF정산표'!$C$42:$C$65,$E10,'CF정산표'!$E$42:$E$65) -> 180000000 | D10: 135000000 | E10: 주식보상비용
A11: CF | B11: 3. 현금의 유입이 없는 수익 등의 차감 | C11: =SUM(C12) -> -12768156 | D11: =SUM(D12) -> -3126488
A12: CF | B12: 외화환산이익 | C12: =SUMIF('CF정산표'!$C$42:$C$65,$E12,'CF정산표'!$E$42:$E$65) -> -12768156 | D12: -3126488 | E12: 외화환산이익
A13: CF | B13: 4. 영업활동으로 인한 자산 · 부채의 변동 | C13: =SUM(C14,C15,C16,C17,C18,C19,C20,C21,C22,C23,C24) -> 50008456 | D13: =SUM(D14,D15,D16,D17,D18,D19,D20,D21,D22,D23,D24) -> 14821693
A14: CF | B14: 매출채권의 증가 | C14: =SUMIF('CF정산표'!$C$42:$C$65,$E14,'CF정산표'!$E$42:$E$65) -> -140127324 | D14: -110248043 | E14: 매출채권의 증가
A15: CF | B15: 미수수익의 감소(증가) | C15: =SUMIF('CF정산표'!$C$42:$C$65,$E15,'CF정산표'!$E$42:$E$65) -> 5441096 | D15: -109002740 | E15: 미수수익의 감소(증가)
A16: CF | B16: 선급비용의 증가 | C16: =SUMIF('CF정산표'!$C$42:$C$65,$E16,'CF정산표'!$E$42:$E$65) -> -45000000 | D16: 0 | E16: 선급비용의 증가
A17: CF | B17: 부가세대급금의 감소(증가) | C17: =SUMIF('CF정산표'!$C$42:$C$65,$E17,'CF정산표'!$E$42:$E$65) -> 39262000 | D17: -24582800 | E17: 부가세대급금의 감소(증가)
A18: CF | B18: 당기법인세자산의 증가 | C18: =SUMIF('CF정산표'!$C$42:$C$65,$E18,'CF정산표'!$E$42:$E$65) -> -18609360 | D18: 0 | E18: 당기법인세자산의 증가
A19: CF | B19: 매입채무의 증가 | C19: =SUMIF('CF정산표'!$C$42:$C$65,$E19,'CF정산표'!$E$42:$E$65) -> 52536000 | D19: 32225600 | E19: 매입채무의 증가
